Workbook

Sheet Summary
A1: Annual savings from better forecasting
A3: Scenario | B3: Safety stock reduction | C3: Stockout reduction | D3: Annual savings ($)
A4: Conservative | B4: =SUM(Scenarios!G2:G4)/SUM(Scenarios!E2:E4) | C4: =SUM(Scenarios!K2:K4)/SUM(Scenarios!M2:M4) | D4: =SUM(Scenarios!L2:L4)
A5: Expected | B5: =SUM(Scenarios!G5:G7)/SUM(Scenarios!E5:E7) | C5: =SUM(Scenarios!K5:K7)/SUM(Scenarios!M5:M7) | D5: =SUM(Scenarios!L5:L7)
A6: Optimistic | B6: =SUM(Scenarios!G8:G10)/SUM(Scenarios!E8:E10) | C6: =SUM(Scenarios!K8:K10)/SUM(Scenarios!M8:M10) | D6: =SUM(Scenarios!L8:L10)
A9: Sensitivity: annual savings ($) by accuracy improvement (sigma reduction, rows) x holding cost (columns)
A10: Improvement \ Holding cost | B10: 0.1 | C10: 0.15 | D10: 0.2 | E10: 0.25 | F10: 0.3 | G10: 0.4
A11: 0.05 | B11: =Assumptions!$B$4*(Data!$B2*SQRT(Assumptions!$B$5))*Assumptions!$B$8*$A11*(Data!$D2*(1-Assumptions!$B$7))*B$10+(Data!$B2*SQRT(Assumptions!$B$5))*Assumptions!$B$9*(Data!$D2*Assumptions!$B$7)*((NORMDIST(Assumptions!$B$4,0,1,FALSE)-Assumptions!$B$4*(1-NORMSDIST(Assumptions!$B$4)))-(1-$A11)*(NORMDIST((Assumptions!$B$4*(1-Assumptions!$B$8*$A11)/(1-$A11)),0,1,FALSE)-(Assumptions!$B$4*(1-Assumptions!$B$8*$A11)/(1-$A11))*(1-NORMSDIST((Assumptions!$B$4*(1-Assumptions!$B$8*$A11)/(1-$A11))))))+Assumptions!$B$4*(Data!$B3*SQRT(Assumptions!$B$5))*Assumptions!$B$8*$A11*(Data!$D3*(1-Assumptions!$B$7))*B$10+(Data!$B3*SQRT(Assumptions!$B$5))*Assumptions!$B$9*(Data!$D3*Assumptions!$B$7)*((NORMDIST(Assumptions!$B$4,0,1,FALSE)-Assumptions!$B$4*(1-NORMSDIST(Assumptions!$B$4)))-(1-$A11)*(NORMDIST((Assumptions!$B$4*(1-Assumptions!$B$8*$A11)/(1-$A11)),0,1,FALSE)-(Assumptions!$B$4*(1-Assumptions!$B$8*$A11)/(1-$A11))*(1-NORMSDIST((Assumptions!$B$4*(1-Assumptions!$B$8*$A11)/(1-$A11))))))+Assumptions!$B$4*(Data!$B4*SQRT(Assumptions!$B$5))*Assumptions!$B$8*$A11*(Data!$D4*(1-Assumptions!$B$7))*B$10+(Data!$B4*SQRT(Assumptions!$B$5))*Assumptions!$B$9*(Data!$D4*Assumptions!$B$7)*((NORMDIST(Assumptions!$B$4,0,1,FALSE)-Assumptions!$B$4*(1-NORMSDIST(Assumptions!$B$4)))-(1-$A11)*(NORMDIST((Assumptions!$B$4*(1-Assumptions!$B$8*$A11)/(1-$A11)),0,1,FALSE)-(Assumptions!$B$4*(1-Assumptions!$B$8*$A11)/(1-$A11))*(1-NORMSDIST((Assumptions!$B$4*(1-Assumptions!$B$8*$A11)/(1-$A11)))))) | C11: =Assumptions!$B$4*(Data!$B2*SQRT(Assumptions!$B$5))*Assumptions!$B$8*$A11*(Data!$D2*(1-Assumptions!$B$7))*C$10+(Data!$B2*SQRT(Assumptions!$B$5))*Assumptions!$B$9*(Data!$D2*Assumptions!$B$7)*((NORMDIST(Assumptions!$B$4,0,1,FALSE)-Assumptions!$B$4*(1-NORMSDIST(Assumptions!$B$4)))-(1-$A11)*(NORMDIST((Assumptions!$B$4*(1-Assumptions!$B$8*$A11)/(1-$A11)),0,1,FALSE)-(Assumptions!$B$4*(1-Assumptions!$B$8*$A11)/(1-$A11))*(1-NORMSDIST((Assumptions!$B$4*(1-Assumptions!$B$8*$A11)/(1-$A11))))))+Assumptions!$B$4*(Data!$B3*SQRT(Assumptions!$B$5))*Assumptions!$B$8*$A11*(Data!$D3*(1-Assumptions!$B$7))*C$10+(Data!$B3*SQRT(Assumptions!$B$5))*Assumptions!$B$9*(Data!$D3*Assumptions!$B$7)*((NORMDIST(Assumptions!$B$4,0,1,FALSE)-Assumptions!$B$4*(1-NORMSDIST(Assumptions!$B$4)))-(1-$A11)*(NORMDIST((Assumptions!$B$4*(1-Assumptions!$B$8*$A11)/(1-$A11)),0,1,FALSE)-(Assumptions!$B$4*(1-Assumptions!$B$8*$A11)/(1-$A11))*(1-NORMSDIST((Assumptions!$B$4*(1-Assumptions!$B$8*$A11)/(1-$A11))))))+Assumptions!$B$4*(Data!$B4*SQRT(Assumptions!$B$5))*Assumptions!$B$8*$A11*(Data!$D4*(1-Assumptions!$B$7))*C$10+(Data!$B4*SQRT(Assumptions!$B$5))*Assumptions!$B$9*(Data!$D4*Assumptions!$B$7)*((NORMDIST(Assumptions!$B$4,0,1,FALSE)-Assumptions!$B$4*(1-NORMSDIST(Assumptions!$B$4)))-(1-$A11)*(NORMDIST((Assumptions!$B$4*(1-Assumptions!$B$8*$A11)/(1-$A11)),0,1,FALSE)-(Assumptions!$B$4*(1-Assumptions!$B$8*$A11)/(1-$A11))*(1-NORMSDIST((Assumptions!$B$4*(1-Assumptions!$B$8*$A11)/(1-$A11)))))) | D11: =Assumptions!$B$4*(Data!$B2*SQRT(Assumptions!$B$5))*Assumptions!$B$8*$A11*(Data!$D2*(1-Assumptions!$B$7))*D$10+(Data!$B2*SQRT(Assumptions!$B$5))*Assumptions!$B$9*(Data!$D2*Assumptions!$B$7)*((NORMDIST(Assumptions!$B$4,0,1,FALSE)-Assumptions!$B$4*(1-NORMSDIST(Assumptions!$B$4)))-(1-$A11)*(NORMDIST((Assumptions!$B$4*(1-Assumptions!$B$8*$A11)/(1-$A11)),0,1,FALSE)-(Assumptions!$B$4*(1-Assumptions!$B$8*$A11)/(1-$A11))*(1-NORMSDIST((Assumptions!$B$4*(1-Assumptions!$B$8*$A11)/(1-$A11))))))+Assumptions!$B$4*(Data!$B3*SQRT(Assumptions!$B$5))*Assumptions!$B$8*$A11*(Data!$D3*(1-Assumptions!$B$7))*D$10+(Data!$B3*SQRT(Assumptions!$B$5))*Assumptions!$B$9*(Data!$D3*Assumptions!$B$7)*((NORMDIST(Assumptions!$B$4,0,1,FALSE)-Assumptions!$B$4*(1-NORMSDIST(Assumptions!$B$4)))-(1-$A11)*(NORMDIST((Assumptions!$B$4*(1-Assumptions!$B$8*$A11)/(1-$A11)),0,1,FALSE)-(Assumptions!$B$4*(1-Assumptions!$B$8*$A11)/(1-$A11))*(1-NORMSDIST((Assumptions!$B$4*(1-Assumptions!$B$8*$A11)/(1-$A11))))))+Assumptions!$B$4*(Data!$B4*SQRT(Assumptions!$B$5))*Assumptions!$B$8*$A11*(Data!$D4*(1-Assumptions!$B$7))*D$10+(Data!$B4*SQRT(Assumptions!$B$5))*Assumptions!$B$9*(Data!$D4*Assumptions!$B$7)*((NORMDIST(Assumptions!$B$4,0,1,FALSE)-Assumptions!$B$4*(1-NORMSDIST(Assumptions!$B$4)))-(1-$A11)*(NORMDIST((Assumptions!$B$4*(1-Assumptions!$B$8*$A11)/(1-$A11)),0,1,FALSE)-(Assumptions!$B$4*(1-Assumptions!$B$8*$A11)/(1-$A11))*(1-NORMSDIST((Assumptions!$B$4*(1-Assumptions!$B$8*$A11)/(1-$A11)))))) | E11: =Assumptions!$B$4*(Data!$B2*SQRT(Assumptions!$B$5))*Assumptions!$B$8*$A11*(Data!$D2*(1-Assumptions!$B$7))*E$10+(Data!$B2*SQRT(Assumptions!$B$5))*Assumptions!$B$9*(Data!$D2*Assumptions!$B$7)*((NORMDIST(Assumptions!$B$4,0,1,FALSE)-Assumptions!$B$4*(1-NORMSDIST(Assumptions!$B$4)))-(1-$A11)*(NORMDIST((Assumptions!$B$4*(1-Assumptions!$B$8*$A11)/(1-$A11)),0,1,FALSE)-(Assumptions!$B$4*(1-Assumptions!$B$8*$A11)/(1-$A11))*(1-NORMSDIST((Assumptions!$B$4*(1-Assumptions!$B$8*$A11)/(1-$A11))))))+Assumptions!$B$4*(Data!$B3*SQRT(Assumptions!$B$5))*Assumptions!$B$8*$A11*(Data!$D3*(1-Assumptions!$B$7))*E$10+(Data!$B3*SQRT(Assumptions!$B$5))*Assumptions!$B$9*(Data!$D3*Assumptions!$B$7)*((NORMDIST(Assumptions!$B$4,0,1,FALSE)-Assumptions!$B$4*(1-NORMSDIST(Assumptions!$B$4)))-(1-$A11)*(NORMDIST((Assumptions!$B$4*(1-Assumptions!$B$8*$A11)/(1-$A11)),0,1,FALSE)-(Assumptions!$B$4*(1-Assumptions!$B$8*$A11)/(1-$A11))*(1-NORMSDIST((Assumptions!$B$4*(1-Assumptions!$B$8*$A11)/(1-$A11))))))+Assumptions!$B$4*(Data!$B4*SQRT(Assumptions!$B$5))*Assumptions!$B$8*$A11*(Data!$D4*(1-Assumptions!$B$7))*E$10+(Data!$B4*SQRT(Assumptions!$B$5))*Assumptions!$B$9*(Data!$D4*Assumptions!$B$7)*((NORMDIST(Assumptions!$B$4,0,1,FALSE)-Assumptions!$B$4*(1-NORMSDIST(Assumptions!$B$4)))-(1-$A11)*(NORMDIST((Assumptions!$B$4*(1-Assumptions!$B$8*$A11)/(1-$A11)),0,1,FALSE)-(Assumptions!$B$4*(1-Assumptions!$B$8*$A11)/(1-$A11))*(1-NORMSDIST((Assumptions!$B$4*(1-Assumptions!$B$8*$A11)/(1-$A11)))))) | F11: =Assumptions!$B$4*(Data!$B2*SQRT(Assumptions!$B$5))*Assumptions!$B$8*$A11*(Data!$D2*(1-Assumptions!$B$7))*F$10+(Data!$B2*SQRT(Assumptions!$B$5))*Assumptions!$B$9*(Data!$D2*Assumptions!$B$7)*((NORMDIST(Assumptions!$B$4,0,1,FALSE)-Assumptions!$B$4*(1-NORMSDIST(Assumptions!$B$4)))-(1-$A11)*(NORMDIST((Assumptions!$B$4*(1-Assumptions!$B$8*$A11)/(1-$A11)),0,1,FALSE)-(Assumptions!$B$4*(1-Assumptions!$B$8*$A11)/(1-$A11))*(1-NORMSDIST((Assumptions!$B$4*(1-Assumptions!$B$8*$A11)/(1-$A11))))))+Assumptions!$B$4*(Data!$B3*SQRT(Assumptions!$B$5))*Assumptions!$B$8*$A11*(Data!$D3*(1-Assumptions!$B$7))*F$10+(Data!$B3*SQRT(Assumptions!$B$5))*Assumptions!$B$9*(Data!$D3*Assumptions!$B$7)*((NORMDIST(Assumptions!$B$4,0,1,FALSE)-Assumptions!$B$4*(1-NORMSDIST(Assumptions!$B$4)))-(1-$A11)*(NORMDIST((Assumptions!$B$4*(1-Assumptions!$B$8*$A11)/(1-$A11)),0,1,FALSE)-(Assumptions!$B$4*(1-Assumptions!$B$8*$A11)/(1-$A11))*(1-NORMSDIST((Assumptions!$B$4*(1-Assumptions!$B$8*$A11)/(1-$A11))))))+Assumptions!$B$4*(Data!$B4*SQRT(Assumptions!$B$5))*Assumptions!$B$8*$A11*(Data!$D4*(1-Assumptions!$B$7))*F$10+(Data!$B4*SQRT(Assumptions!$B$5))*Assumptions!$B$9*(Data!$D4*Assumptions!$B$7)*((NORMDIST(Assumptions!$B$4,0,1,FALSE)-Assumptions!$B$4*(1-NORMSDIST(Assumptions!$B$4)))-(1-$A11)*(NORMDIST((Assumptions!$B$4*(1-Assumptions!$B$8*$A11)/(1-$A11)),0,1,FALSE)-(Assumptions!$B$4*(1-Assumptions!$B$8*$A11)/(1-$A11))*(1-NORMSDIST((Assumptions!$B$4*(1-Assumptions!$B$8*$A11)/(1-$A11)))))) | G11: =Assumptions!$B$4*(Data!$B2*SQRT(Assumptions!$B$5))*Assumptions!$B$8*$A11*(Data!$D2*(1-Assumptions!$B$7))*G$10+(Data!$B2*SQRT(Assumptions!$B$5))*Assumptions!$B$9*(Data!$D2*Assumptions!$B$7)*((NORMDIST(Assumptions!$B$4,0,1,FALSE)-Assumptions!$B$4*(1-NORMSDIST(Assumptions!$B$4)))-(1-$A11)*(NORMDIST((Assumptions!$B$4*(1-Assumptions!$B$8*$A11)/(1-$A11)),0,1,FALSE)-(Assumptions!$B$4*(1-Assumptions!$B$8*$A11)/(1-$A11))*(1-NORMSDIST((Assumptions!$B$4*(1-Assumptions!$B$8*$A11)/(1-$A11))))))+Assumptions!$B$4*(Data!$B3*SQRT(Assumptions!$B$5))*Assumptions!$B$8*$A11*(Data!$D3*(1-Assumptions!$B$7))*G$10+(Data!$B3*SQRT(Assumptions!$B$5))*Assumptions!$B$9*(Data!$D3*Assumptions!$B$7)*((NORMDIST(Assumptions!$B$4,0,1,FALSE)-Assumptions!$B$4*(1-NORMSDIST(Assumptions!$B$4)))-(1-$A11)*(NORMDIST((Assumptions!$B$4*(1-Assumptions!$B$8*$A11)/(1-$A11)),0,1,FALSE)-(Assumptions!$B$4*(1-Assumptions!$B$8*$A11)/(1-$A11))*(1-NORMSDIST((Assumptions!$B$4*(1-Assumptions!$B$8*$A11)/(1-$A11))))))+Assumptions!$B$4*(Data!$B4*SQRT(Assumptions!$B$5))*Assumptions!$B$8*$A11*(Data!$D4*(1-Assumptions!$B$7))*G$10+(Data!$B4*SQRT(Assumptions!$B$5))*Assumptions!$B$9*(Data!$D4*Assumptions!$B$7)*((NORMDIST(Assumptions!$B$4,0,1,FALSE)-Assumptions!$B$4*(1-NORMSDIST(Assumptions!$B$4)))-(1-$A11)*(NORMDIST((Assumptions!$B$4*(1-Assumptions!$B$8*$A11)/(1-$A11)),0,1,FALSE)-(Assumptions!$B$4*(1-Assumptions!$B$8*$A11)/(1-$A11))*(1-NORMSDIST((Assumptions!$B$4*(1-Assumptions!$B$8*$A11)/(1-$A11))))))
A12: 0.1 | B12: =Assumptions!$B$4*(Data!$B2*SQRT(Assumptions!$B$5))*Assumptions!$B$8*$A12*(Data!$D2*(1-Assumptions!$B$7))*B$10+(Data!$B2*SQRT(Assumptions!$B$5))*Assumptions!$B$9*(Data!$D2*Assumptions!$B$7)*((NORMDIST(Assumptions!$B$4,0,1,FALSE)-Assumptions!$B$4*(1-NORMSDIST(Assumptions!$B$4)))-(1-$A12)*(NORMDIST((Assumptions!$B$4*(1-Assumptions!$B$8*$A12)/(1-$A12)),0,1,FALSE)-(Assumptions!$B$4*(1-Assumptions!$B$8*$A12)/(1-$A12))*(1-NORMSDIST((Assumptions!$B$4*(1-Assumptions!$B$8*$A12)/(1-$A12))))))+Assumptions!$B$4*(Data!$B3*SQRT(Assumptions!$B$5))*Assumptions!$B$8*$A12*(Data!$D3*(1-Assumptions!$B$7))*B$10+(Data!$B3*SQRT(Assumptions!$B$5))*Assumptions!$B$9*(Data!$D3*Assumptions!$B$7)*((NORMDIST(Assumptions!$B$4,0,1,FALSE)-Assumptions!$B$4*(1-NORMSDIST(Assumptions!$B$4)))-(1-$A12)*(NORMDIST((Assumptions!$B$4*(1-Assumptions!$B$8*$A12)/(1-$A12)),0,1,FALSE)-(Assumptions!$B$4*(1-Assumptions!$B$8*$A12)/(1-$A12))*(1-NORMSDIST((Assumptions!$B$4*(1-Assumptions!$B$8*$A12)/(1-$A12))))))+Assumptions!$B$4*(Data!$B4*SQRT(Assumptions!$B$5))*Assumptions!$B$8*$A12*(Data!$D4*(1-Assumptions!$B$7))*B$10+(Data!$B4*SQRT(Assumptions!$B$5))*Assumptions!$B$9*(Data!$D4*Assumptions!$B$7)*((NORMDIST(Assumptions!$B$4,0,1,FALSE)-Assumptions!$B$4*(1-NORMSDIST(Assumptions!$B$4)))-(1-$A12)*(NORMDIST((Assumptions!$B$4*(1-Assumptions!$B$8*$A12)/(1-$A12)),0,1,FALSE)-(Assumptions!$B$4*(1-Assumptions!$B$8*$A12)/(1-$A12))*(1-NORMSDIST((Assumptions!$B$4*(1-Assumptions!$B$8*$A12)/(1-$A12)))))) | C12: =Assumptions!$B$4*(Data!$B2*SQRT(Assumptions!$B$5))*Assumptions!$B$8*$A12*(Data!$D2*(1-Assumptions!$B$7))*C$10+(Data!$B2*SQRT(Assumptions!$B$5))*Assumptions!$B$9*(Data!$D2*Assumptions!$B$7)*((NORMDIST(Assumptions!$B$4,0,1,FALSE)-Assumptions!$B$4*(1-NORMSDIST(Assumptions!$B$4)))-(1-$A12)*(NORMDIST((Assumptions!$B$4*(1-Assumptions!$B$8*$A12)/(1-$A12)),0,1,FALSE)-(Assumptions!$B$4*(1-Assumptions!$B$8*$A12)/(1-$A12))*(1-NORMSDIST((Assumptions!$B$4*(1-Assumptions!$B$8*$A12)/(1-$A12))))))+Assumptions!$B$4*(Data!$B3*SQRT(Assumptions!$B$5))*Assumptions!$B$8*$A12*(Data!$D3*(1-Assumptions!$B$7))*C$10+(Data!$B3*SQRT(Assumptions!$B$5))*Assumptions!$B$9*(Data!$D3*Assumptions!$B$7)*((NORMDIST(Assumptions!$B$4,0,1,FALSE)-Assumptions!$B$4*(1-NORMSDIST(Assumptions!$B$4)))-(1-$A12)*(NORMDIST((Assumptions!$B$4*(1-Assumptions!$B$8*$A12)/(1-$A12)),0,1,FALSE)-(Assumptions!$B$4*(1-Assumptions!$B$8*$A12)/(1-$A12))*(1-NORMSDIST((Assumptions!$B$4*(1-Assumptions!$B$8*$A12)/(1-$A12))))))+Assumptions!$B$4*(Data!$B4*SQRT(Assumptions!$B$5))*Assumptions!$B$8*$A12*(Data!$D4*(1-Assumptions!$B$7))*C$10+(Data!$B4*SQRT(Assumptions!$B$5))*Assumptions!$B$9*(Data!$D4*Assumptions!$B$7)*((NORMDIST(Assumptions!$B$4,0,1,FALSE)-Assumptions!$B$4*(1-NORMSDIST(Assumptions!$B$4)))-(1-$A12)*(NORMDIST((Assumptions!$B$4*(1-Assumptions!$B$8*$A12)/(1-$A12)),0,1,FALSE)-(Assumptions!$B$4*(1-Assumptions!$B$8*$A12)/(1-$A12))*(1-NORMSDIST((Assumptions!$B$4*(1-Assumptions!$B$8*$A12)/(1-$A12)))))) | D12: =Assumptions!$B$4*(Data!$B2*SQRT(Assumptions!$B$5))*Assumptions!$B$8*$A12*(Data!$D2*(1-Assumptions!$B$7))*D$10+(Data!$B2*SQRT(Assumptions!$B$5))*Assumptions!$B$9*(Data!$D2*Assumptions!$B$7)*((NORMDIST(Assumptions!$B$4,0,1,FALSE)-Assumptions!$B$4*(1-NORMSDIST(Assumptions!$B$4)))-(1-$A12)*(NORMDIST((Assumptions!$B$4*(1-Assumptions!$B$8*$A12)/(1-$A12)),0,1,FALSE)-(Assumptions!$B$4*(1-Assumptions!$B$8*$A12)/(1-$A12))*(1-NORMSDIST((Assumptions!$B$4*(1-Assumptions!$B$8*$A12)/(1-$A12))))))+Assumptions!$B$4*(Data!$B3*SQRT(Assumptions!$B$5))*Assumptions!$B$8*$A12*(Data!$D3*(1-Assumptions!$B$7))*D$10+(Data!$B3*SQRT(Assumptions!$B$5))*Assumptions!$B$9*(Data!$D3*Assumptions!$B$7)*((NORMDIST(Assumptions!$B$4,0,1,FALSE)-Assumptions!$B$4*(1-NORMSDIST(Assumptions!$B$4)))-(1-$A12)*(NORMDIST((Assumptions!$B$4*(1-Assumptions!$B$8*$A12)/(1-$A12)),0,1,FALSE)-(Assumptions!$B$4*(1-Assumptions!$B$8*$A12)/(1-$A12))*(1-NORMSDIST((Assumptions!$B$4*(1-Assumptions!$B$8*$A12)/(1-$A12))))))+Assumptions!$B$4*(Data!$B4*SQRT(Assumptions!$B$5))*Assumptions!$B$8*$A12*(Data!$D4*(1-Assumptions!$B$7))*D$10+(Data!$B4*SQRT(Assumptions!$B$5))*Assumptions!$B$9*(Data!$D4*Assumptions!$B$7)*((NORMDIST(Assumptions!$B$4,0,1,FALSE)-Assumptions!$B$4*(1-NORMSDIST(Assumptions!$B$4)))-(1-$A12)*(NORMDIST((Assumptions!$B$4*(1-Assumptions!$B$8*$A12)/(1-$A12)),0,1,FALSE)-(Assumptions!$B$4*(1-Assumptions!$B$8*$A12)/(1-$A12))*(1-NORMSDIST((Assumptions!$B$4*(1-Assumptions!$B$8*$A12)/(1-$A12)))))) | E12: =Assumptions!$B$4*(Data!$B2*SQRT(Assumptions!$B$5))*Assumptions!$B$8*$A12*(Data!$D2*(1-Assumptions!$B$7))*E$10+(Data!$B2*SQRT(Assumptions!$B$5))*Assumptions!$B$9*(Data!$D2*Assumptions!$B$7)*((NORMDIST(Assumptions!$B$4,0,1,FALSE)-Assumptions!$B$4*(1-NORMSDIST(Assumptions!$B$4)))-(1-$A12)*(NORMDIST((Assumptions!$B$4*(1-Assumptions!$B$8*$A12)/(1-$A12)),0,1,FALSE)-(Assumptions!$B$4*(1-Assumptions!$B$8*$A12)/(1-$A12))*(1-NORMSDIST((Assumptions!$B$4*(1-Assumptions!$B$8*$A12)/(1-$A12))))))+Assumptions!$B$4*(Data!$B3*SQRT(Assumptions!$B$5))*Assumptions!$B$8*$A12*(Data!$D3*(1-Assumptions!$B$7))*E$10+(Data!$B3*SQRT(Assumptions!$B$5))*Assumptions!$B$9*(Data!$D3*Assumptions!$B$7)*((NORMDIST(Assumptions!$B$4,0,1,FALSE)-Assumptions!$B$4*(1-NORMSDIST(Assumptions!$B$4)))-(1-$A12)*(NORMDIST((Assumptions!$B$4*(1-Assumptions!$B$8*$A12)/(1-$A12)),0,1,FALSE)-(Assumptions!$B$4*(1-Assumptions!$B$8*$A12)/(1-$A12))*(1-NORMSDIST((Assumptions!$B$4*(1-Assumptions!$B$8*$A12)/(1-$A12))))))+Assumptions!$B$4*(Data!$B4*SQRT(Assumptions!$B$5))*Assumptions!$B$8*$A12*(Data!$D4*(1-Assumptions!$B$7))*E$10+(Data!$B4*SQRT(Assumptions!$B$5))*Assumptions!$B$9*(Data!$D4*Assumptions!$B$7)*((NORMDIST(Assumptions!$B$4,0,1,FALSE)-Assumptions!$B$4*(1-NORMSDIST(Assumptions!$B$4)))-(1-$A12)*(NORMDIST((Assumptions!$B$4*(1-Assumptions!$B$8*$A12)/(1-$A12)),0,1,FALSE)-(Assumptions!$B$4*(1-Assumptions!$B$8*$A12)/(1-$A12))*(1-NORMSDIST((Assumptions!$B$4*(1-Assumptions!$B$8*$A12)/(1-$A12)))))) | F12: =Assumptions!$B$4*(Data!$B2*SQRT(Assumptions!$B$5))*Assumptions!$B$8*$A12*(Data!$D2*(1-Assumptions!$B$7))*F$10+(Data!$B2*SQRT(Assumptions!$B$5))*Assumptions!$B$9*(Data!$D2*Assumptions!$B$7)*((NORMDIST(Assumptions!$B$4,0,1,FALSE)-Assumptions!$B$4*(1-NORMSDIST(Assumptions!$B$4)))-(1-$A12)*(NORMDIST((Assumptions!$B$4*(1-Assumptions!$B$8*$A12)/(1-$A12)),0,1,FALSE)-(Assumptions!$B$4*(1-Assumptions!$B$8*$A12)/(1-$A12))*(1-NORMSDIST((Assumptions!$B$4*(1-Assumptions!$B$8*$A12)/(1-$A12))))))+Assumptions!$B$4*(Data!$B3*SQRT(Assumptions!$B$5))*Assumptions!$B$8*$A12*(Data!$D3*(1-Assumptions!$B$7))*F$10+(Data!$B3*SQRT(Assumptions!$B$5))*Assumptions!$B$9*(Data!$D3*Assumptions!$B$7)*((NORMDIST(Assumptions!$B$4,0,1,FALSE)-Assumptions!$B$4*(1-NORMSDIST(Assumptions!$B$4)))-(1-$A12)*(NORMDIST((Assumptions!$B$4*(1-Assumptions!$B$8*$A12)/(1-$A12)),0,1,FALSE)-(Assumptions!$B$4*(1-Assumptions!$B$8*$A12)/(1-$A12))*(1-NORMSDIST((Assumptions!$B$4*(1-Assumptions!$B$8*$A12)/(1-$A12))))))+Assumptions!$B$4*(Data!$B4*SQRT(Assumptions!$B$5))*Assumptions!$B$8*$A12*(Data!$D4*(1-Assumptions!$B$7))*F$10+(Data!$B4*SQRT(Assumptions!$B$5))*Assumptions!$B$9*(Data!$D4*Assumptions!$B$7)*((NORMDIST(Assumptions!$B$4,0,1,FALSE)-Assumptions!$B$4*(1-NORMSDIST(Assumptions!$B$4)))-(1-$A12)*(NORMDIST((Assumptions!$B$4*(1-Assumptions!$B$8*$A12)/(1-$A12)),0,1,FALSE)-(Assumptions!$B$4*(1-Assumptions!$B$8*$A12)/(1-$A12))*(1-NORMSDIST((Assumptions!$B$4*(1-Assumptions!$B$8*$A12)/(1-$A12)))))) | G12: =Assumptions!$B$4*(Data!$B2*SQRT(Assumptions!$B$5))*Assumptions!$B$8*$A12*(Data!$D2*(1-Assumptions!$B$7))*G$10+(Data!$B2*SQRT(Assumptions!$B$5))*Assumptions!$B$9*(Data!$D2*Assumptions!$B$7)*((NORMDIST(Assumptions!$B$4,0,1,FALSE)-Assumptions!$B$4*(1-NORMSDIST(Assumptions!$B$4)))-(1-$A12)*(NORMDIST((Assumptions!$B$4*(1-Assumptions!$B$8*$A12)/(1-$A12)),0,1,FALSE)-(Assumptions!$B$4*(1-Assumptions!$B$8*$A12)/(1-$A12))*(1-NORMSDIST((Assumptions!$B$4*(1-Assumptions!$B$8*$A12)/(1-$A12))))))+Assumptions!$B$4*(Data!$B3*SQRT(Assumptions!$B$5))*Assumptions!$B$8*$A12*(Data!$D3*(1-Assumptions!$B$7))*G$10+(Data!$B3*SQRT(Assumptions!$B$5))*Assumptions!$B$9*(Data!$D3*Assumptions!$B$7)*((NORMDIST(Assumptions!$B$4,0,1,FALSE)-Assumptions!$B$4*(1-NORMSDIST(Assumptions!$B$4)))-(1-$A12)*(NORMDIST((Assumptions!$B$4*(1-Assumptions!$B$8*$A12)/(1-$A12)),0,1,FALSE)-(Assumptions!$B$4*(1-Assumptions!$B$8*$A12)/(1-$A12))*(1-NORMSDIST((Assumptions!$B$4*(1-Assumptions!$B$8*$A12)/(1-$A12))))))+Assumptions!$B$4*(Data!$B4*SQRT(Assumptions!$B$5))*Assumptions!$B$8*$A12*(Data!$D4*(1-Assumptions!$B$7))*G$10+(Data!$B4*SQRT(Assumptions!$B$5))*Assumptions!$B$9*(Data!$D4*Assumptions!$B$7)*((NORMDIST(Assumptions!$B$4,0,1,FALSE)-Assumptions!$B$4*(1-NORMSDIST(Assumptions!$B$4)))-(1-$A12)*(NORMDIST((Assumptions!$B$4*(1-Assumptions!$B$8*$A12)/(1-$A12)),0,1,FALSE)-(Assumptions!$B$4*(1-Assumptions!$B$8*$A12)/(1-$A12))*(1-NORMSDIST((Assumptions!$B$4*(1-Assumptions!$B$8*$A12)/(1-$A12))))))
A13: 0.15 | B13: =Assumptions!$B$4*(Data!$B2*SQRT(Assumptions!$B$5))*Assumptions!$B$8*$A13*(Data!$D2*(1-Assumptions!$B$7))*B$10+(Data!$B2*SQRT(Assumptions!$B$5))*Assumptions!$B$9*(Data!$D2*Assumptions!$B$7)*((NORMDIST(Assumptions!$B$4,0,1,FALSE)-Assumptions!$B$4*(1-NORMSDIST(Assumptions!$B$4)))-(1-$A13)*(NORMDIST((Assumptions!$B$4*(1-Assumptions!$B$8*$A13)/(1-$A13)),0,1,FALSE)-(Assumptions!$B$4*(1-Assumptions!$B$8*$A13)/(1-$A13))*(1-NORMSDIST((Assumptions!$B$4*(1-Assumptions!$B$8*$A13)/(1-$A13))))))+Assumptions!$B$4*(Data!$B3*SQRT(Assumptions!$B$5))*Assumptions!$B$8*$A13*(Data!$D3*(1-Assumptions!$B$7))*B$10+(Data!$B3*SQRT(Assumptions!$B$5))*Assumptions!$B$9*(Data!$D3*Assumptions!$B$7)*((NORMDIST(Assumptions!$B$4,0,1,FALSE)-Assumptions!$B$4*(1-NORMSDIST(Assumptions!$B$4)))-(1-$A13)*(NORMDIST((Assumptions!$B$4*(1-Assumptions!$B$8*$A13)/(1-$A13)),0,1,FALSE)-(Assumptions!$B$4*(1-Assumptions!$B$8*$A13)/(1-$A13))*(1-NORMSDIST((Assumptions!$B$4*(1-Assumptions!$B$8*$A13)/(1-$A13))))))+Assumptions!$B$4*(Data!$B4*SQRT(Assumptions!$B$5))*Assumptions!$B$8*$A13*(Data!$D4*(1-Assumptions!$B$7))*B$10+(Data!$B4*SQRT(Assumptions!$B$5))*Assumptions!$B$9*(Data!$D4*Assumptions!$B$7)*((NORMDIST(Assumptions!$B$4,0,1,FALSE)-Assumptions!$B$4*(1-NORMSDIST(Assumptions!$B$4)))-(1-$A13)*(NORMDIST((Assumptions!$B$4*(1-Assumptions!$B$8*$A13)/(1-$A13)),0,1,FALSE)-(Assumptions!$B$4*(1-Assumptions!$B$8*$A13)/(1-$A13))*(1-NORMSDIST((Assumptions!$B$4*(1-Assumptions!$B$8*$A13)/(1-$A13)))))) | C13: =Assumptions!$B$4*(Data!$B2*SQRT(Assumptions!$B$5))*Assumptions!$B$8*$A13*(Data!$D2*(1-Assumptions!$B$7))*C$10+(Data!$B2*SQRT(Assumptions!$B$5))*Assumptions!$B$9*(Data!$D2*Assumptions!$B$7)*((NORMDIST(Assumptions!$B$4,0,1,FALSE)-Assumptions!$B$4*(1-NORMSDIST(Assumptions!$B$4)))-(1-$A13)*(NORMDIST((Assumptions!$B$4*(1-Assumptions!$B$8*$A13)/(1-$A13)),0,1,FALSE)-(Assumptions!$B$4*(1-Assumptions!$B$8*$A13)/(1-$A13))*(1-NORMSDIST((Assumptions!$B$4*(1-Assumptions!$B$8*$A13)/(1-$A13))))))+Assumptions!$B$4*(Data!$B3*SQRT(Assumptions!$B$5))*Assumptions!$B$8*$A13*(Data!$D3*(1-Assumptions!$B$7))*C$10+(Data!$B3*SQRT(Assumptions!$B$5))*Assumptions!$B$9*(Data!$D3*Assumptions!$B$7)*((NORMDIST(Assumptions!$B$4,0,1,FALSE)-Assumptions!$B$4*(1-NORMSDIST(Assumptions!$B$4)))-(1-$A13)*(NORMDIST((Assumptions!$B$4*(1-Assumptions!$B$8*$A13)/(1-$A13)),0,1,FALSE)-(Assumptions!$B$4*(1-Assumptions!$B$8*$A13)/(1-$A13))*(1-NORMSDIST((Assumptions!$B$4*(1-Assumptions!$B$8*$A13)/(1-$A13))))))+Assumptions!$B$4*(Data!$B4*SQRT(Assumptions!$B$5))*Assumptions!$B$8*$A13*(Data!$D4*(1-Assumptions!$B$7))*C$10+(Data!$B4*SQRT(Assumptions!$B$5))*Assumptions!$B$9*(Data!$D4*Assumptions!$B$7)*((NORMDIST(Assumptions!$B$4,0,1,FALSE)-Assumptions!$B$4*(1-NORMSDIST(Assumptions!$B$4)))-(1-$A13)*(NORMDIST((Assumptions!$B$4*(1-Assumptions!$B$8*$A13)/(1-$A13)),0,1,FALSE)-(Assumptions!$B$4*(1-Assumptions!$B$8*$A13)/(1-$A13))*(1-NORMSDIST((Assumptions!$B$4*(1-Assumptions!$B$8*$A13)/(1-$A13)))))) | D13: =Assumptions!$B$4*(Data!$B2*SQRT(Assumptions!$B$5))*Assumptions!$B$8*$A13*(Data!$D2*(1-Assumptions!$B$7))*D$10+(Data!$B2*SQRT(Assumptions!$B$5))*Assumptions!$B$9*(Data!$D2*Assumptions!$B$7)*((NORMDIST(Assumptions!$B$4,0,1,FALSE)-Assumptions!$B$4*(1-NORMSDIST(Assumptions!$B$4)))-(1-$A13)*(NORMDIST((Assumptions!$B$4*(1-Assumptions!$B$8*$A13)/(1-$A13)),0,1,FALSE)-(Assumptions!$B$4*(1-Assumptions!$B$8*$A13)/(1-$A13))*(1-NORMSDIST((Assumptions!$B$4*(1-Assumptions!$B$8*$A13)/(1-$A13))))))+Assumptions!$B$4*(Data!$B3*SQRT(Assumptions!$B$5))*Assumptions!$B$8*$A13*(Data!$D3*(1-Assumptions!$B$7))*D$10+(Data!$B3*SQRT(Assumptions!$B$5))*Assumptions!$B$9*(Data!$D3*Assumptions!$B$7)*((NORMDIST(Assumptions!$B$4,0,1,FALSE)-Assumptions!$B$4*(1-NORMSDIST(Assumptions!$B$4)))-(1-$A13)*(NORMDIST((Assumptions!$B$4*(1-Assumptions!$B$8*$A13)/(1-$A13)),0,1,FALSE)-(Assumptions!$B$4*(1-Assumptions!$B$8*$A13)/(1-$A13))*(1-NORMSDIST((Assumptions!$B$4*(1-Assumptions!$B$8*$A13)/(1-$A13))))))+Assumptions!$B$4*(Data!$B4*SQRT(Assumptions!$B$5))*Assumptions!$B$8*$A13*(Data!$D4*(1-Assumptions!$B$7))*D$10+(Data!$B4*SQRT(Assumptions!$B$5))*Assumptions!$B$9*(Data!$D4*Assumptions!$B$7)*((NORMDIST(Assumptions!$B$4,0,1,FALSE)-Assumptions!$B$4*(1-NORMSDIST(Assumptions!$B$4)))-(1-$A13)*(NORMDIST((Assumptions!$B$4*(1-Assumptions!$B$8*$A13)/(1-$A13)),0,1,FALSE)-(Assumptions!$B$4*(1-Assumptions!$B$8*$A13)/(1-$A13))*(1-NORMSDIST((Assumptions!$B$4*(1-Assumptions!$B$8*$A13)/(1-$A13)))))) | E13: =Assumptions!$B$4*(Data!$B2*SQRT(Assumptions!$B$5))*Assumptions!$B$8*$A13*(Data!$D2*(1-Assumptions!$B$7))*E$10+(Data!$B2*SQRT(Assumptions!$B$5))*Assumptions!$B$9*(Data!$D2*Assumptions!$B$7)*((NORMDIST(Assumptions!$B$4,0,1,FALSE)-Assumptions!$B$4*(1-NORMSDIST(Assumptions!$B$4)))-(1-$A13)*(NORMDIST((Assumptions!$B$4*(1-Assumptions!$B$8*$A13)/(1-$A13)),0,1,FALSE)-(Assumptions!$B$4*(1-Assumptions!$B$8*$A13)/(1-$A13))*(1-NORMSDIST((Assumptions!$B$4*(1-Assumptions!$B$8*$A13)/(1-$A13))))))+Assumptions!$B$4*(Data!$B3*SQRT(Assumptions!$B$5))*Assumptions!$B$8*$A13*(Data!$D3*(1-Assumptions!$B$7))*E$10+(Data!$B3*SQRT(Assumptions!$B$5))*Assumptions!$B$9*(Data!$D3*Assumptions!$B$7)*((NORMDIST(Assumptions!$B$4,0,1,FALSE)-Assumptions!$B$4*(1-NORMSDIST(Assumptions!$B$4)))-(1-$A13)*(NORMDIST((Assumptions!$B$4*(1-Assumptions!$B$8*$A13)/(1-$A13)),0,1,FALSE)-(Assumptions!$B$4*(1-Assumptions!$B$8*$A13)/(1-$A13))*(1-NORMSDIST((Assumptions!$B$4*(1-Assumptions!$B$8*$A13)/(1-$A13))))))+Assumptions!$B$4*(Data!$B4*SQRT(Assumptions!$B$5))*Assumptions!$B$8*$A13*(Data!$D4*(1-Assumptions!$B$7))*E$10+(Data!$B4*SQRT(Assumptions!$B$5))*Assumptions!$B$9*(Data!$D4*Assumptions!$B$7)*((NORMDIST(Assumptions!$B$4,0,1,FALSE)-Assumptions!$B$4*(1-NORMSDIST(Assumptions!$B$4)))-(1-$A13)*(NORMDIST((Assumptions!$B$4*(1-Assumptions!$B$8*$A13)/(1-$A13)),0,1,FALSE)-(Assumptions!$B$4*(1-Assumptions!$B$8*$A13)/(1-$A13))*(1-NORMSDIST((Assumptions!$B$4*(1-Assumptions!$B$8*$A13)/(1-$A13)))))) | F13: =Assumptions!$B$4*(Data!$B2*SQRT(Assumptions!$B$5))*Assumptions!$B$8*$A13*(Data!$D2*(1-Assumptions!$B$7))*F$10+(Data!$B2*SQRT(Assumptions!$B$5))*Assumptions!$B$9*(Data!$D2*Assumptions!$B$7)*((NORMDIST(Assumptions!$B$4,0,1,FALSE)-Assumptions!$B$4*(1-NORMSDIST(Assumptions!$B$4)))-(1-$A13)*(NORMDIST((Assumptions!$B$4*(1-Assumptions!$B$8*$A13)/(1-$A13)),0,1,FALSE)-(Assumptions!$B$4*(1-Assumptions!$B$8*$A13)/(1-$A13))*(1-NORMSDIST((Assumptions!$B$4*(1-Assumptions!$B$8*$A13)/(1-$A13))))))+Assumptions!$B$4*(Data!$B3*SQRT(Assumptions!$B$5))*Assumptions!$B$8*$A13*(Data!$D3*(1-Assumptions!$B$7))*F$10+(Data!$B3*SQRT(Assumptions!$B$5))*Assumptions!$B$9*(Data!$D3*Assumptions!$B$7)*((NORMDIST(Assumptions!$B$4,0,1,FALSE)-Assumptions!$B$4*(1-NORMSDIST(Assumptions!$B$4)))-(1-$A13)*(NORMDIST((Assumptions!$B$4*(1-Assumptions!$B$8*$A13)/(1-$A13)),0,1,FALSE)-(Assumptions!$B$4*(1-Assumptions!$B$8*$A13)/(1-$A13))*(1-NORMSDIST((Assumptions!$B$4*(1-Assumptions!$B$8*$A13)/(1-$A13))))))+Assumptions!$B$4*(Data!$B4*SQRT(Assumptions!$B$5))*Assumptions!$B$8*$A13*(Data!$D4*(1-Assumptions!$B$7))*F$10+(Data!$B4*SQRT(Assumptions!$B$5))*Assumptions!$B$9*(Data!$D4*Assumptions!$B$7)*((NORMDIST(Assumptions!$B$4,0,1,FALSE)-Assumptions!$B$4*(1-NORMSDIST(Assumptions!$B$4)))-(1-$A13)*(NORMDIST((Assumptions!$B$4*(1-Assumptions!$B$8*$A13)/(1-$A13)),0,1,FALSE)-(Assumptions!$B$4*(1-Assumptions!$B$8*$A13)/(1-$A13))*(1-NORMSDIST((Assumptions!$B$4*(1-Assumptions!$B$8*$A13)/(1-$A13)))))) | G13: =Assumptions!$B$4*(Data!$B2*SQRT(Assumptions!$B$5))*Assumptions!$B$8*$A13*(Data!$D2*(1-Assumptions!$B$7))*G$10+(Data!$B2*SQRT(Assumptions!$B$5))*Assumptions!$B$9*(Data!$D2*Assumptions!$B$7)*((NORMDIST(Assumptions!$B$4,0,1,FALSE)-Assumptions!$B$4*(1-NORMSDIST(Assumptions!$B$4)))-(1-$A13)*(NORMDIST((Assumptions!$B$4*(1-Assumptions!$B$8*$A13)/(1-$A13)),0,1,FALSE)-(Assumptions!$B$4*(1-Assumptions!$B$8*$A13)/(1-$A13))*(1-NORMSDIST((Assumptions!$B$4*(1-Assumptions!$B$8*$A13)/(1-$A13))))))+Assumptions!$B$4*(Data!$B3*SQRT(Assumptions!$B$5))*Assumptions!$B$8*$A13*(Data!$D3*(1-Assumptions!$B$7))*G$10+(Data!$B3*SQRT(Assumptions!$B$5))*Assumptions!$B$9*(Data!$D3*Assumptions!$B$7)*((NORMDIST(Assumptions!$B$4,0,1,FALSE)-Assumptions!$B$4*(1-NORMSDIST(Assumptions!$B$4)))-(1-$A13)*(NORMDIST((Assumptions!$B$4*(1-Assumptions!$B$8*$A13)/(1-$A13)),0,1,FALSE)-(Assumptions!$B$4*(1-Assumptions!$B$8*$A13)/(1-$A13))*(1-NORMSDIST((Assumptions!$B$4*(1-Assumptions!$B$8*$A13)/(1-$A13))))))+Assumptions!$B$4*(Data!$B4*SQRT(Assumptions!$B$5))*Assumptions!$B$8*$A13*(Data!$D4*(1-Assumptions!$B$7))*G$10+(Data!$B4*SQRT(Assumptions!$B$5))*Assumptions!$B$9*(Data!$D4*Assumptions!$B$7)*((NORMDIST(Assumptions!$B$4,0,1,FALSE)-Assumptions!$B$4*(1-NORMSDIST(Assumptions!$B$4)))-(1-$A13)*(NORMDIST((Assumptions!$B$4*(1-Assumptions!$B$8*$A13)/(1-$A13)),0,1,FALSE)-(Assumptions!$B$4*(1-Assumptions!$B$8*$A13)/(1-$A13))*(1-NORMSDIST((Assumptions!$B$4*(1-Assumptions!$B$8*$A13)/(1-$A13))))))
A14: 0.2 | B14: =Assumptions!$B$4*(Data!$B2*SQRT(Assumptions!$B$5))*Assumptions!$B$8*$A14*(Data!$D2*(1-Assumptions!$B$7))*B$10+(Data!$B2*SQRT(Assumptions!$B$5))*Assumptions!$B$9*(Data!$D2*Assumptions!$B$7)*((NORMDIST(Assumptions!$B$4,0,1,FALSE)-Assumptions!$B$4*(1-NORMSDIST(Assumptions!$B$4)))-(1-$A14)*(NORMDIST((Assumptions!$B$4*(1-Assumptions!$B$8*$A14)/(1-$A14)),0,1,FALSE)-(Assumptions!$B$4*(1-Assumptions!$B$8*$A14)/(1-$A14))*(1-NORMSDIST((Assumptions!$B$4*(1-Assumptions!$B$8*$A14)/(1-$A14))))))+Assumptions!$B$4*(Data!$B3*SQRT(Assumptions!$B$5))*Assumptions!$B$8*$A14*(Data!$D3*(1-Assumptions!$B$7))*B$10+(Data!$B3*SQRT(Assumptions!$B$5))*Assumptions!$B$9*(Data!$D3*Assumptions!$B$7)*((NORMDIST(Assumptions!$B$4,0,1,FALSE)-Assumptions!$B$4*(1-NORMSDIST(Assumptions!$B$4)))-(1-$A14)*(NORMDIST((Assumptions!$B$4*(1-Assumptions!$B$8*$A14)/(1-$A14)),0,1,FALSE)-(Assumptions!$B$4*(1-Assumptions!$B$8*$A14)/(1-$A14))*(1-NORMSDIST((Assumptions!$B$4*(1-Assumptions!$B$8*$A14)/(1-$A14))))))+Assumptions!$B$4*(Data!$B4*SQRT(Assumptions!$B$5))*Assumptions!$B$8*$A14*(Data!$D4*(1-Assumptions!$B$7))*B$10+(Data!$B4*SQRT(Assumptions!$B$5))*Assumptions!$B$9*(Data!$D4*Assumptions!$B$7)*((NORMDIST(Assumptions!$B$4,0,1,FALSE)-Assumptions!$B$4*(1-NORMSDIST(Assumptions!$B$4)))-(1-$A14)*(NORMDIST((Assumptions!$B$4*(1-Assumptions!$B$8*$A14)/(1-$A14)),0,1,FALSE)-(Assumptions!$B$4*(1-Assumptions!$B$8*$A14)/(1-$A14))*(1-NORMSDIST((Assumptions!$B$4*(1-Assumptions!$B$8*$A14)/(1-$A14)))))) | C14: =Assumptions!$B$4*(Data!$B2*SQRT(Assumptions!$B$5))*Assumptions!$B$8*$A14*(Data!$D2*(1-Assumptions!$B$7))*C$10+(Data!$B2*SQRT(Assumptions!$B$5))*Assumptions!$B$9*(Data!$D2*Assumptions!$B$7)*((NORMDIST(Assumptions!$B$4,0,1,FALSE)-Assumptions!$B$4*(1-NORMSDIST(Assumptions!$B$4)))-(1-$A14)*(NORMDIST((Assumptions!$B$4*(1-Assumptions!$B$8*$A14)/(1-$A14)),0,1,FALSE)-(Assumptions!$B$4*(1-Assumptions!$B$8*$A14)/(1-$A14))*(1-NORMSDIST((Assumptions!$B$4*(1-Assumptions!$B$8*$A14)/(1-$A14))))))+Assumptions!$B$4*(Data!$B3*SQRT(Assumptions!$B$5))*Assumptions!$B$8*$A14*(Data!$D3*(1-Assumptions!$B$7))*C$10+(Data!$B3*SQRT(Assumptions!$B$5))*Assumptions!$B$9*(Data!$D3*Assumptions!$B$7)*((NORMDIST(Assumptions!$B$4,0,1,FALSE)-Assumptions!$B$4*(1-NORMSDIST(Assumptions!$B$4)))-(1-$A14)*(NORMDIST((Assumptions!$B$4*(1-Assumptions!$B$8*$A14)/(1-$A14)),0,1,FALSE)-(Assumptions!$B$4*(1-Assumptions!$B$8*$A14)/(1-$A14))*(1-NORMSDIST((Assumptions!$B$4*(1-Assumptions!$B$8*$A14)/(1-$A14))))))+Assumptions!$B$4*(Data!$B4*SQRT(Assumptions!$B$5))*Assumptions!$B$8*$A14*(Data!$D4*(1-Assumptions!$B$7))*C$10+(Data!$B4*SQRT(Assumptions!$B$5))*Assumptions!$B$9*(Data!$D4*Assumptions!$B$7)*((NORMDIST(Assumptions!$B$4,0,1,FALSE)-Assumptions!$B$4*(1-NORMSDIST(Assumptions!$B$4)))-(1-$A14)*(NORMDIST((Assumptions!$B$4*(1-Assumptions!$B$8*$A14)/(1-$A14)),0,1,FALSE)-(Assumptions!$B$4*(1-Assumptions!$B$8*$A14)/(1-$A14))*(1-NORMSDIST((Assumptions!$B$4*(1-Assumptions!$B$8*$A14)/(1-$A14)))))) | D14: =Assumptions!$B$4*(Data!$B2*SQRT(Assumptions!$B$5))*Assumptions!$B$8*$A14*(Data!$D2*(1-Assumptions!$B$7))*D$10+(Data!$B2*SQRT(Assumptions!$B$5))*Assumptions!$B$9*(Data!$D2*Assumptions!$B$7)*((NORMDIST(Assumptions!$B$4,0,1,FALSE)-Assumptions!$B$4*(1-NORMSDIST(Assumptions!$B$4)))-(1-$A14)*(NORMDIST((Assumptions!$B$4*(1-Assumptions!$B$8*$A14)/(1-$A14)),0,1,FALSE)-(Assumptions!$B$4*(1-Assumptions!$B$8*$A14)/(1-$A14))*(1-NORMSDIST((Assumptions!$B$4*(1-Assumptions!$B$8*$A14)/(1-$A14))))))+Assumptions!$B$4*(Data!$B3*SQRT(Assumptions!$B$5))*Assumptions!$B$8*$A14*(Data!$D3*(1-Assumptions!$B$7))*D$10+(Data!$B3*SQRT(Assumptions!$B$5))*Assumptions!$B$9*(Data!$D3*Assumptions!$B$7)*((NORMDIST(Assumptions!$B$4,0,1,FALSE)-Assumptions!$B$4*(1-NORMSDIST(Assumptions!$B$4)))-(1-$A14)*(NORMDIST((Assumptions!$B$4*(1-Assumptions!$B$8*$A14)/(1-$A14)),0,1,FALSE)-(Assumptions!$B$4*(1-Assumptions!$B$8*$A14)/(1-$A14))*(1-NORMSDIST((Assumptions!$B$4*(1-Assumptions!$B$8*$A14)/(1-$A14))))))+Assumptions!$B$4*(Data!$B4*SQRT(Assumptions!$B$5))*Assumptions!$B$8*$A14*(Data!$D4*(1-Assumptions!$B$7))*D$10+(Data!$B4*SQRT(Assumptions!$B$5))*Assumptions!$B$9*(Data!$D4*Assumptions!$B$7)*((NORMDIST(Assumptions!$B$4,0,1,FALSE)-Assumptions!$B$4*(1-NORMSDIST(Assumptions!$B$4)))-(1-$A14)*(NORMDIST((Assumptions!$B$4*(1-Assumptions!$B$8*$A14)/(1-$A14)),0,1,FALSE)-(Assumptions!$B$4*(1-Assumptions!$B$8*$A14)/(1-$A14))*(1-NORMSDIST((Assumptions!$B$4*(1-Assumptions!$B$8*$A14)/(1-$A14)))))) | E14: =Assumptions!$B$4*(Data!$B2*SQRT(Assumptions!$B$5))*Assumptions!$B$8*$A14*(Data!$D2*(1-Assumptions!$B$7))*E$10+(Data!$B2*SQRT(Assumptions!$B$5))*Assumptions!$B$9*(Data!$D2*Assumptions!$B$7)*((NORMDIST(Assumptions!$B$4,0,1,FALSE)-Assumptions!$B$4*(1-NORMSDIST(Assumptions!$B$4)))-(1-$A14)*(NORMDIST((Assumptions!$B$4*(1-Assumptions!$B$8*$A14)/(1-$A14)),0,1,FALSE)-(Assumptions!$B$4*(1-Assumptions!$B$8*$A14)/(1-$A14))*(1-NORMSDIST((Assumptions!$B$4*(1-Assumptions!$B$8*$A14)/(1-$A14))))))+Assumptions!$B$4*(Data!$B3*SQRT(Assumptions!$B$5))*Assumptions!$B$8*$A14*(Data!$D3*(1-Assumptions!$B$7))*E$10+(Data!$B3*SQRT(Assumptions!$B$5))*Assumptions!$B$9*(Data!$D3*Assumptions!$B$7)*((NORMDIST(Assumptions!$B$4,0,1,FALSE)-Assumptions!$B$4*(1-NORMSDIST(Assumptions!$B$4)))-(1-$A14)*(NORMDIST((Assumptions!$B$4*(1-Assumptions!$B$8*$A14)/(1-$A14)),0,1,FALSE)-(Assumptions!$B$4*(1-Assumptions!$B$8*$A14)/(1-$A14))*(1-NORMSDIST((Assumptions!$B$4*(1-Assumptions!$B$8*$A14)/(1-$A14))))))+Assumptions!$B$4*(Data!$B4*SQRT(Assumptions!$B$5))*Assumptions!$B$8*$A14*(Data!$D4*(1-Assumptions!$B$7))*E$10+(Data!$B4*SQRT(Assumptions!$B$5))*Assumptions!$B$9*(Data!$D4*Assumptions!$B$7)*((NORMDIST(Assumptions!$B$4,0,1,FALSE)-Assumptions!$B$4*(1-NORMSDIST(Assumptions!$B$4)))-(1-$A14)*(NORMDIST((Assumptions!$B$4*(1-Assumptions!$B$8*$A14)/(1-$A14)),0,1,FALSE)-(Assumptions!$B$4*(1-Assumptions!$B$8*$A14)/(1-$A14))*(1-NORMSDIST((Assumptions!$B$4*(1-Assumptions!$B$8*$A14)/(1-$A14)))))) | F14: =Assumptions!$B$4*(Data!$B2*SQRT(Assumptions!$B$5))*Assumptions!$B$8*$A14*(Data!$D2*(1-Assumptions!$B$7))*F$10+(Data!$B2*SQRT(Assumptions!$B$5))*Assumptions!$B$9*(Data!$D2*Assumptions!$B$7)*((NORMDIST(Assumptions!$B$4,0,1,FALSE)-Assumptions!$B$4*(1-NORMSDIST(Assumptions!$B$4)))-(1-$A14)*(NORMDIST((Assumptions!$B$4*(1-Assumptions!$B$8*$A14)/(1-$A14)),0,1,FALSE)-(Assumptions!$B$4*(1-Assumptions!$B$8*$A14)/(1-$A14))*(1-NORMSDIST((Assumptions!$B$4*(1-Assumptions!$B$8*$A14)/(1-$A14))))))+Assumptions!$B$4*(Data!$B3*SQRT(Assumptions!$B$5))*Assumptions!$B$8*$A14*(Data!$D3*(1-Assumptions!$B$7))*F$10+(Data!$B3*SQRT(Assumptions!$B$5))*Assumptions!$B$9*(Data!$D3*Assumptions!$B$7)*((NORMDIST(Assumptions!$B$4,0,1,FALSE)-Assumptions!$B$4*(1-NORMSDIST(Assumptions!$B$4)))-(1-$A14)*(NORMDIST((Assumptions!$B$4*(1-Assumptions!$B$8*$A14)/(1-$A14)),0,1,FALSE)-(Assumptions!$B$4*(1-Assumptions!$B$8*$A14)/(1-$A14))*(1-NORMSDIST((Assumptions!$B$4*(1-Assumptions!$B$8*$A14)/(1-$A14))))))+Assumptions!$B$4*(Data!$B4*SQRT(Assumptions!$B$5))*Assumptions!$B$8*$A14*(Data!$D4*(1-Assumptions!$B$7))*F$10+(Data!$B4*SQRT(Assumptions!$B$5))*Assumptions!$B$9*(Data!$D4*Assumptions!$B$7)*((NORMDIST(Assumptions!$B$4,0,1,FALSE)-Assumptions!$B$4*(1-NORMSDIST(Assumptions!$B$4)))-(1-$A14)*(NORMDIST((Assumptions!$B$4*(1-Assumptions!$B$8*$A14)/(1-$A14)),0,1,FALSE)-(Assumptions!$B$4*(1-Assumptions!$B$8*$A14)/(1-$A14))*(1-NORMSDIST((Assumptions!$B$4*(1-Assumptions!$B$8*$A14)/(1-$A14)))))) | G14: =Assumptions!$B$4*(Data!$B2*SQRT(Assumptions!$B$5))*Assumptions!$B$8*$A14*(Data!$D2*(1-Assumptions!$B$7))*G$10+(Data!$B2*SQRT(Assumptions!$B$5))*Assumptions!$B$9*(Data!$D2*Assumptions!$B$7)*((NORMDIST(Assumptions!$B$4,0,1,FALSE)-Assumptions!$B$4*(1-NORMSDIST(Assumptions!$B$4)))-(1-$A14)*(NORMDIST((Assumptions!$B$4*(1-Assumptions!$B$8*$A14)/(1-$A14)),0,1,FALSE)-(Assumptions!$B$4*(1-Assumptions!$B$8*$A14)/(1-$A14))*(1-NORMSDIST((Assumptions!$B$4*(1-Assumptions!$B$8*$A14)/(1-$A14))))))+Assumptions!$B$4*(Data!$B3*SQRT(Assumptions!$B$5))*Assumptions!$B$8*$A14*(Data!$D3*(1-Assumptions!$B$7))*G$10+(Data!$B3*SQRT(Assumptions!$B$5))*Assumptions!$B$9*(Data!$D3*Assumptions!$B$7)*((NORMDIST(Assumptions!$B$4,0,1,FALSE)-Assumptions!$B$4*(1-NORMSDIST(Assumptions!$B$4)))-(1-$A14)*(NORMDIST((Assumptions!$B$4*(1-Assumptions!$B$8*$A14)/(1-$A14)),0,1,FALSE)-(Assumptions!$B$4*(1-Assumptions!$B$8*$A14)/(1-$A14))*(1-NORMSDIST((Assumptions!$B$4*(1-Assumptions!$B$8*$A14)/(1-$A14))))))+Assumptions!$B$4*(Data!$B4*SQRT(Assumptions!$B$5))*Assumptions!$B$8*$A14*(Data!$D4*(1-Assumptions!$B$7))*G$10+(Data!$B4*SQRT(Assumptions!$B$5))*Assumptions!$B$9*(Data!$D4*Assumptions!$B$7)*((NORMDIST(Assumptions!$B$4,0,1,FALSE)-Assumptions!$B$4*(1-NORMSDIST(Assumptions!$B$4)))-(1-$A14)*(NORMDIST((Assumptions!$B$4*(1-Assumptions!$B$8*$A14)/(1-$A14)),0,1,FALSE)-(Assumptions!$B$4*(1-Assumptions!$B$8*$A14)/(1-$A14))*(1-NORMSDIST((Assumptions!$B$4*(1-Assumptions!$B$8*$A14)/(1-$A14))))))
A15: 0.25 | B15: =Assumptions!$B$4*(Data!$B2*SQRT(Assumptions!$B$5))*Assumptions!$B$8*$A15*(Data!$D2*(1-Assumptions!$B$7))*B$10+(Data!$B2*SQRT(Assumptions!$B$5))*Assumptions!$B$9*(Data!$D2*Assumptions!$B$7)*((NORMDIST(Assumptions!$B$4,0,1,FALSE)-Assumptions!$B$4*(1-NORMSDIST(Assumptions!$B$4)))-(1-$A15)*(NORMDIST((Assumptions!$B$4*(1-Assumptions!$B$8*$A15)/(1-$A15)),0,1,FALSE)-(Assumptions!$B$4*(1-Assumptions!$B$8*$A15)/(1-$A15))*(1-NORMSDIST((Assumptions!$B$4*(1-Assumptions!$B$8*$A15)/(1-$A15))))))+Assumptions!$B$4*(Data!$B3*SQRT(Assumptions!$B$5))*Assumptions!$B$8*$A15*(Data!$D3*(1-Assumptions!$B$7))*B$10+(Data!$B3*SQRT(Assumptions!$B$5))*Assumptions!$B$9*(Data!$D3*Assumptions!$B$7)*((NORMDIST(Assumptions!$B$4,0,1,FALSE)-Assumptions!$B$4*(1-NORMSDIST(Assumptions!$B$4)))-(1-$A15)*(NORMDIST((Assumptions!$B$4*(1-Assumptions!$B$8*$A15)/(1-$A15)),0,1,FALSE)-(Assumptions!$B$4*(1-Assumptions!$B$8*$A15)/(1-$A15))*(1-NORMSDIST((Assumptions!$B$4*(1-Assumptions!$B$8*$A15)/(1-$A15))))))+Assumptions!$B$4*(Data!$B4*SQRT(Assumptions!$B$5))*Assumptions!$B$8*$A15*(Data!$D4*(1-Assumptions!$B$7))*B$10+(Data!$B4*SQRT(Assumptions!$B$5))*Assumptions!$B$9*(Data!$D4*Assumptions!$B$7)*((NORMDIST(Assumptions!$B$4,0,1,FALSE)-Assumptions!$B$4*(1-NORMSDIST(Assumptions!$B$4)))-(1-$A15)*(NORMDIST((Assumptions!$B$4*(1-Assumptions!$B$8*$A15)/(1-$A15)),0,1,FALSE)-(Assumptions!$B$4*(1-Assumptions!$B$8*$A15)/(1-$A15))*(1-NORMSDIST((Assumptions!$B$4*(1-Assumptions!$B$8*$A15)/(1-$A15)))))) | C15: =Assumptions!$B$4*(Data!$B2*SQRT(Assumptions!$B$5))*Assumptions!$B$8*$A15*(Data!$D2*(1-Assumptions!$B$7))*C$10+(Data!$B2*SQRT(Assumptions!$B$5))*Assumptions!$B$9*(Data!$D2*Assumptions!$B$7)*((NORMDIST(Assumptions!$B$4,0,1,FALSE)-Assumptions!$B$4*(1-NORMSDIST(Assumptions!$B$4)))-(1-$A15)*(NORMDIST((Assumptions!$B$4*(1-Assumptions!$B$8*$A15)/(1-$A15)),0,1,FALSE)-(Assumptions!$B$4*(1-Assumptions!$B$8*$A15)/(1-$A15))*(1-NORMSDIST((Assumptions!$B$4*(1-Assumptions!$B$8*$A15)/(1-$A15))))))+Assumptions!$B$4*(Data!$B3*SQRT(Assumptions!$B$5))*Assumptions!$B$8*$A15*(Data!$D3*(1-Assumptions!$B$7))*C$10+(Data!$B3*SQRT(Assumptions!$B$5))*Assumptions!$B$9*(Data!$D3*Assumptions!$B$7)*((NORMDIST(Assumptions!$B$4,0,1,FALSE)-Assumptions!$B$4*(1-NORMSDIST(Assumptions!$B$4)))-(1-$A15)*(NORMDIST((Assumptions!$B$4*(1-Assumptions!$B$8*$A15)/(1-$A15)),0,1,FALSE)-(Assumptions!$B$4*(1-Assumptions!$B$8*$A15)/(1-$A15))*(1-NORMSDIST((Assumptions!$B$4*(1-Assumptions!$B$8*$A15)/(1-$A15))))))+Assumptions!$B$4*(Data!$B4*SQRT(Assumptions!$B$5))*Assumptions!$B$8*$A15*(Data!$D4*(1-Assumptions!$B$7))*C$10+(Data!$B4*SQRT(Assumptions!$B$5))*Assumptions!$B$9*(Data!$D4*Assumptions!$B$7)*((NORMDIST(Assumptions!$B$4,0,1,FALSE)-Assumptions!$B$4*(1-NORMSDIST(Assumptions!$B$4)))-(1-$A15)*(NORMDIST((Assumptions!$B$4*(1-Assumptions!$B$8*$A15)/(1-$A15)),0,1,FALSE)-(Assumptions!$B$4*(1-Assumptions!$B$8*$A15)/(1-$A15))*(1-NORMSDIST((Assumptions!$B$4*(1-Assumptions!$B$8*$A15)/(1-$A15)))))) | D15: =Assumptions!$B$4*(Data!$B2*SQRT(Assumptions!$B$5))*Assumptions!$B$8*$A15*(Data!$D2*(1-Assumptions!$B$7))*D$10+(Data!$B2*SQRT(Assumptions!$B$5))*Assumptions!$B$9*(Data!$D2*Assumptions!$B$7)*((NORMDIST(Assumptions!$B$4,0,1,FALSE)-Assumptions!$B$4*(1-NORMSDIST(Assumptions!$B$4)))-(1-$A15)*(NORMDIST((Assumptions!$B$4*(1-Assumptions!$B$8*$A15)/(1-$A15)),0,1,FALSE)-(Assumptions!$B$4*(1-Assumptions!$B$8*$A15)/(1-$A15))*(1-NORMSDIST((Assumptions!$B$4*(1-Assumptions!$B$8*$A15)/(1-$A15))))))+Assumptions!$B$4*(Data!$B3*SQRT(Assumptions!$B$5))*Assumptions!$B$8*$A15*(Data!$D3*(1-Assumptions!$B$7))*D$10+(Data!$B3*SQRT(Assumptions!$B$5))*Assumptions!$B$9*(Data!$D3*Assumptions!$B$7)*((NORMDIST(Assumptions!$B$4,0,1,FALSE)-Assumptions!$B$4*(1-NORMSDIST(Assumptions!$B$4)))-(1-$A15)*(NORMDIST((Assumptions!$B$4*(1-Assumptions!$B$8*$A15)/(1-$A15)),0,1,FALSE)-(Assumptions!$B$4*(1-Assumptions!$B$8*$A15)/(1-$A15))*(1-NORMSDIST((Assumptions!$B$4*(1-Assumptions!$B$8*$A15)/(1-$A15))))))+Assumptions!$B$4*(Data!$B4*SQRT(Assumptions!$B$5))*Assumptions!$B$8*$A15*(Data!$D4*(1-Assumptions!$B$7))*D$10+(Data!$B4*SQRT(Assumptions!$B$5))*Assumptions!$B$9*(Data!$D4*Assumptions!$B$7)*((NORMDIST(Assumptions!$B$4,0,1,FALSE)-Assumptions!$B$4*(1-NORMSDIST(Assumptions!$B$4)))-(1-$A15)*(NORMDIST((Assumptions!$B$4*(1-Assumptions!$B$8*$A15)/(1-$A15)),0,1,FALSE)-(Assumptions!$B$4*(1-Assumptions!$B$8*$A15)/(1-$A15))*(1-NORMSDIST((Assumptions!$B$4*(1-Assumptions!$B$8*$A15)/(1-$A15)))))) | E15: =Assumptions!$B$4*(Data!$B2*SQRT(Assumptions!$B$5))*Assumptions!$B$8*$A15*(Data!$D2*(1-Assumptions!$B$7))*E$10+(Data!$B2*SQRT(Assumptions!$B$5))*Assumptions!$B$9*(Data!$D2*Assumptions!$B$7)*((NORMDIST(Assumptions!$B$4,0,1,FALSE)-Assumptions!$B$4*(1-NORMSDIST(Assumptions!$B$4)))-(1-$A15)*(NORMDIST((Assumptions!$B$4*(1-Assumptions!$B$8*$A15)/(1-$A15)),0,1,FALSE)-(Assumptions!$B$4*(1-Assumptions!$B$8*$A15)/(1-$A15))*(1-NORMSDIST((Assumptions!$B$4*(1-Assumptions!$B$8*$A15)/(1-$A15))))))+Assumptions!$B$4*(Data!$B3*SQRT(Assumptions!$B$5))*Assumptions!$B$8*$A15*(Data!$D3*(1-Assumptions!$B$7))*E$10+(Data!$B3*SQRT(Assumptions!$B$5))*Assumptions!$B$9*(Data!$D3*Assumptions!$B$7)*((NORMDIST(Assumptions!$B$4,0,1,FALSE)-Assumptions!$B$4*(1-NORMSDIST(Assumptions!$B$4)))-(1-$A15)*(NORMDIST((Assumptions!$B$4*(1-Assumptions!$B$8*$A15)/(1-$A15)),0,1,FALSE)-(Assumptions!$B$4*(1-Assumptions!$B$8*$A15)/(1-$A15))*(1-NORMSDIST((Assumptions!$B$4*(1-Assumptions!$B$8*$A15)/(1-$A15))))))+Assumptions!$B$4*(Data!$B4*SQRT(Assumptions!$B$5))*Assumptions!$B$8*$A15*(Data!$D4*(1-Assumptions!$B$7))*E$10+(Data!$B4*SQRT(Assumptions!$B$5))*Assumptions!$B$9*(Data!$D4*Assumptions!$B$7)*((NORMDIST(Assumptions!$B$4,0,1,FALSE)-Assumptions!$B$4*(1-NORMSDIST(Assumptions!$B$4)))-(1-$A15)*(NORMDIST((Assumptions!$B$4*(1-Assumptions!$B$8*$A15)/(1-$A15)),0,1,FALSE)-(Assumptions!$B$4*(1-Assumptions!$B$8*$A15)/(1-$A15))*(1-NORMSDIST((Assumptions!$B$4*(1-Assumptions!$B$8*$A15)/(1-$A15)))))) | F15: =Assumptions!$B$4*(Data!$B2*SQRT(Assumptions!$B$5))*Assumptions!$B$8*$A15*(Data!$D2*(1-Assumptions!$B$7))*F$10+(Data!$B2*SQRT(Assumptions!$B$5))*Assumptions!$B$9*(Data!$D2*Assumptions!$B$7)*((NORMDIST(Assumptions!$B$4,0,1,FALSE)-Assumptions!$B$4*(1-NORMSDIST(Assumptions!$B$4)))-(1-$A15)*(NORMDIST((Assumptions!$B$4*(1-Assumptions!$B$8*$A15)/(1-$A15)),0,1,FALSE)-(Assumptions!$B$4*(1-Assumptions!$B$8*$A15)/(1-$A15))*(1-NORMSDIST((Assumptions!$B$4*(1-Assumptions!$B$8*$A15)/(1-$A15))))))+Assumptions!$B$4*(Data!$B3*SQRT(Assumptions!$B$5))*Assumptions!$B$8*$A15*(Data!$D3*(1-Assumptions!$B$7))*F$10+(Data!$B3*SQRT(Assumptions!$B$5))*Assumptions!$B$9*(Data!$D3*Assumptions!$B$7)*((NORMDIST(Assumptions!$B$4,0,1,FALSE)-Assumptions!$B$4*(1-NORMSDIST(Assumptions!$B$4)))-(1-$A15)*(NORMDIST((Assumptions!$B$4*(1-Assumptions!$B$8*$A15)/(1-$A15)),0,1,FALSE)-(Assumptions!$B$4*(1-Assumptions!$B$8*$A15)/(1-$A15))*(1-NORMSDIST((Assumptions!$B$4*(1-Assumptions!$B$8*$A15)/(1-$A15))))))+Assumptions!$B$4*(Data!$B4*SQRT(Assumptions!$B$5))*Assumptions!$B$8*$A15*(Data!$D4*(1-Assumptions!$B$7))*F$10+(Data!$B4*SQRT(Assumptions!$B$5))*Assumptions!$B$9*(Data!$D4*Assumptions!$B$7)*((NORMDIST(Assumptions!$B$4,0,1,FALSE)-Assumptions!$B$4*(1-NORMSDIST(Assumptions!$B$4)))-(1-$A15)*(NORMDIST((Assumptions!$B$4*(1-Assumptions!$B$8*$A15)/(1-$A15)),0,1,FALSE)-(Assumptions!$B$4*(1-Assumptions!$B$8*$A15)/(1-$A15))*(1-NORMSDIST((Assumptions!$B$4*(1-Assumptions!$B$8*$A15)/(1-$A15)))))) | G15: =Assumptions!$B$4*(Data!$B2*SQRT(Assumptions!$B$5))*Assumptions!$B$8*$A15*(Data!$D2*(1-Assumptions!$B$7))*G$10+(Data!$B2*SQRT(Assumptions!$B$5))*Assumptions!$B$9*(Data!$D2*Assumptions!$B$7)*((NORMDIST(Assumptions!$B$4,0,1,FALSE)-Assumptions!$B$4*(1-NORMSDIST(Assumptions!$B$4)))-(1-$A15)*(NORMDIST((Assumptions!$B$4*(1-Assumptions!$B$8*$A15)/(1-$A15)),0,1,FALSE)-(Assumptions!$B$4*(1-Assumptions!$B$8*$A15)/(1-$A15))*(1-NORMSDIST((Assumptions!$B$4*(1-Assumptions!$B$8*$A15)/(1-$A15))))))+Assumptions!$B$4*(Data!$B3*SQRT(Assumptions!$B$5))*Assumptions!$B$8*$A15*(Data!$D3*(1-Assumptions!$B$7))*G$10+(Data!$B3*SQRT(Assumptions!$B$5))*Assumptions!$B$9*(Data!$D3*Assumptions!$B$7)*((NORMDIST(Assumptions!$B$4,0,1,FALSE)-Assumptions!$B$4*(1-NORMSDIST(Assumptions!$B$4)))-(1-$A15)*(NORMDIST((Assumptions!$B$4*(1-Assumptions!$B$8*$A15)/(1-$A15)),0,1,FALSE)-(Assumptions!$B$4*(1-Assumptions!$B$8*$A15)/(1-$A15))*(1-NORMSDIST((Assumptions!$B$4*(1-Assumptions!$B$8*$A15)/(1-$A15))))))+Assumptions!$B$4*(Data!$B4*SQRT(Assumptions!$B$5))*Assumptions!$B$8*$A15*(Data!$D4*(1-Assumptions!$B$7))*G$10+(Data!$B4*SQRT(Assumptions!$B$5))*Assumptions!$B$9*(Data!$D4*Assumptions!$B$7)*((NORMDIST(Assumptions!$B$4,0,1,FALSE)-Assumptions!$B$4*(1-NORMSDIST(Assumptions!$B$4)))-(1-$A15)*(NORMDIST((Assumptions!$B$4*(1-Assumptions!$B$8*$A15)/(1-$A15)),0,1,FALSE)-(Assumptions!$B$4*(1-Assumptions!$B$8*$A15)/(1-$A15))*(1-NORMSDIST((Assumptions!$B$4*(1-Assumptions!$B$8*$A15)/(1-$A15))))))
A16: 0.3 | B16: =Assumptions!$B$4*(Data!$B2*SQRT(Assumptions!$B$5))*Assumptions!$B$8*$A16*(Data!$D2*(1-Assumptions!$B$7))*B$10+(Data!$B2*SQRT(Assumptions!$B$5))*Assumptions!$B$9*(Data!$D2*Assumptions!$B$7)*((NORMDIST(Assumptions!$B$4,0,1,FALSE)-Assumptions!$B$4*(1-NORMSDIST(Assumptions!$B$4)))-(1-$A16)*(NORMDIST((Assumptions!$B$4*(1-Assumptions!$B$8*$A16)/(1-$A16)),0,1,FALSE)-(Assumptions!$B$4*(1-Assumptions!$B$8*$A16)/(1-$A16))*(1-NORMSDIST((Assumptions!$B$4*(1-Assumptions!$B$8*$A16)/(1-$A16))))))+Assumptions!$B$4*(Data!$B3*SQRT(Assumptions!$B$5))*Assumptions!$B$8*$A16*(Data!$D3*(1-Assumptions!$B$7))*B$10+(Data!$B3*SQRT(Assumptions!$B$5))*Assumptions!$B$9*(Data!$D3*Assumptions!$B$7)*((NORMDIST(Assumptions!$B$4,0,1,FALSE)-Assumptions!$B$4*(1-NORMSDIST(Assumptions!$B$4)))-(1-$A16)*(NORMDIST((Assumptions!$B$4*(1-Assumptions!$B$8*$A16)/(1-$A16)),0,1,FALSE)-(Assumptions!$B$4*(1-Assumptions!$B$8*$A16)/(1-$A16))*(1-NORMSDIST((Assumptions!$B$4*(1-Assumptions!$B$8*$A16)/(1-$A16))))))+Assumptions!$B$4*(Data!$B4*SQRT(Assumptions!$B$5))*Assumptions!$B$8*$A16*(Data!$D4*(1-Assumptions!$B$7))*B$10+(Data!$B4*SQRT(Assumptions!$B$5))*Assumptions!$B$9*(Data!$D4*Assumptions!$B$7)*((NORMDIST(Assumptions!$B$4,0,1,FALSE)-Assumptions!$B$4*(1-NORMSDIST(Assumptions!$B$4)))-(1-$A16)*(NORMDIST((Assumptions!$B$4*(1-Assumptions!$B$8*$A16)/(1-$A16)),0,1,FALSE)-(Assumptions!$B$4*(1-Assumptions!$B$8*$A16)/(1-$A16))*(1-NORMSDIST((Assumptions!$B$4*(1-Assumptions!$B$8*$A16)/(1-$A16)))))) | C16: =Assumptions!$B$4*(Data!$B2*SQRT(Assumptions!$B$5))*Assumptions!$B$8*$A16*(Data!$D2*(1-Assumptions!$B$7))*C$10+(Data!$B2*SQRT(Assumptions!$B$5))*Assumptions!$B$9*(Data!$D2*Assumptions!$B$7)*((NORMDIST(Assumptions!$B$4,0,1,FALSE)-Assumptions!$B$4*(1-NORMSDIST(Assumptions!$B$4)))-(1-$A16)*(NORMDIST((Assumptions!$B$4*(1-Assumptions!$B$8*$A16)/(1-$A16)),0,1,FALSE)-(Assumptions!$B$4*(1-Assumptions!$B$8*$A16)/(1-$A16))*(1-NORMSDIST((Assumptions!$B$4*(1-Assumptions!$B$8*$A16)/(1-$A16))))))+Assumptions!$B$4*(Data!$B3*SQRT(Assumptions!$B$5))*Assumptions!$B$8*$A16*(Data!$D3*(1-Assumptions!$B$7))*C$10+(Data!$B3*SQRT(Assumptions!$B$5))*Assumptions!$B$9*(Data!$D3*Assumptions!$B$7)*((NORMDIST(Assumptions!$B$4,0,1,FALSE)-Assumptions!$B$4*(1-NORMSDIST(Assumptions!$B$4)))-(1-$A16)*(NORMDIST((Assumptions!$B$4*(1-Assumptions!$B$8*$A16)/(1-$A16)),0,1,FALSE)-(Assumptions!$B$4*(1-Assumptions!$B$8*$A16)/(1-$A16))*(1-NORMSDIST((Assumptions!$B$4*(1-Assumptions!$B$8*$A16)/(1-$A16))))))+Assumptions!$B$4*(Data!$B4*SQRT(Assumptions!$B$5))*Assumptions!$B$8*$A16*(Data!$D4*(1-Assumptions!$B$7))*C$10+(Data!$B4*SQRT(Assumptions!$B$5))*Assumptions!$B$9*(Data!$D4*Assumptions!$B$7)*((NORMDIST(Assumptions!$B$4,0,1,FALSE)-Assumptions!$B$4*(1-NORMSDIST(Assumptions!$B$4)))-(1-$A16)*(NORMDIST((Assumptions!$B$4*(1-Assumptions!$B$8*$A16)/(1-$A16)),0,1,FALSE)-(Assumptions!$B$4*(1-Assumptions!$B$8*$A16)/(1-$A16))*(1-NORMSDIST((Assumptions!$B$4*(1-Assumptions!$B$8*$A16)/(1-$A16)))))) | D16: =Assumptions!$B$4*(Data!$B2*SQRT(Assumptions!$B$5))*Assumptions!$B$8*$A16*(Data!$D2*(1-Assumptions!$B$7))*D$10+(Data!$B2*SQRT(Assumptions!$B$5))*Assumptions!$B$9*(Data!$D2*Assumptions!$B$7)*((NORMDIST(Assumptions!$B$4,0,1,FALSE)-Assumptions!$B$4*(1-NORMSDIST(Assumptions!$B$4)))-(1-$A16)*(NORMDIST((Assumptions!$B$4*(1-Assumptions!$B$8*$A16)/(1-$A16)),0,1,FALSE)-(Assumptions!$B$4*(1-Assumptions!$B$8*$A16)/(1-$A16))*(1-NORMSDIST((Assumptions!$B$4*(1-Assumptions!$B$8*$A16)/(1-$A16))))))+Assumptions!$B$4*(Data!$B3*SQRT(Assumptions!$B$5))*Assumptions!$B$8*$A16*(Data!$D3*(1-Assumptions!$B$7))*D$10+(Data!$B3*SQRT(Assumptions!$B$5))*Assumptions!$B$9*(Data!$D3*Assumptions!$B$7)*((NORMDIST(Assumptions!$B$4,0,1,FALSE)-Assumptions!$B$4*(1-NORMSDIST(Assumptions!$B$4)))-(1-$A16)*(NORMDIST((Assumptions!$B$4*(1-Assumptions!$B$8*$A16)/(1-$A16)),0,1,FALSE)-(Assumptions!$B$4*(1-Assumptions!$B$8*$A16)/(1-$A16))*(1-NORMSDIST((Assumptions!$B$4*(1-Assumptions!$B$8*$A16)/(1-$A16))))))+Assumptions!$B$4*(Data!$B4*SQRT(Assumptions!$B$5))*Assumptions!$B$8*$A16*(Data!$D4*(1-Assumptions!$B$7))*D$10+(Data!$B4*SQRT(Assumptions!$B$5))*Assumptions!$B$9*(Data!$D4*Assumptions!$B$7)*((NORMDIST(Assumptions!$B$4,0,1,FALSE)-Assumptions!$B$4*(1-NORMSDIST(Assumptions!$B$4)))-(1-$A16)*(NORMDIST((Assumptions!$B$4*(1-Assumptions!$B$8*$A16)/(1-$A16)),0,1,FALSE)-(Assumptions!$B$4*(1-Assumptions!$B$8*$A16)/(1-$A16))*(1-NORMSDIST((Assumptions!$B$4*(1-Assumptions!$B$8*$A16)/(1-$A16)))))) | E16: =Assumptions!$B$4*(Data!$B2*SQRT(Assumptions!$B$5))*Assumptions!$B$8*$A16*(Data!$D2*(1-Assumptions!$B$7))*E$10+(Data!$B2*SQRT(Assumptions!$B$5))*Assumptions!$B$9*(Data!$D2*Assumptions!$B$7)*((NORMDIST(Assumptions!$B$4,0,1,FALSE)-Assumptions!$B$4*(1-NORMSDIST(Assumptions!$B$4)))-(1-$A16)*(NORMDIST((Assumptions!$B$4*(1-Assumptions!$B$8*$A16)/(1-$A16)),0,1,FALSE)-(Assumptions!$B$4*(1-Assumptions!$B$8*$A16)/(1-$A16))*(1-NORMSDIST((Assumptions!$B$4*(1-Assumptions!$B$8*$A16)/(1-$A16))))))+Assumptions!$B$4*(Data!$B3*SQRT(Assumptions!$B$5))*Assumptions!$B$8*$A16*(Data!$D3*(1-Assumptions!$B$7))*E$10+(Data!$B3*SQRT(Assumptions!$B$5))*Assumptions!$B$9*(Data!$D3*Assumptions!$B$7)*((NORMDIST(Assumptions!$B$4,0,1,FALSE)-Assumptions!$B$4*(1-NORMSDIST(Assumptions!$B$4)))-(1-$A16)*(NORMDIST((Assumptions!$B$4*(1-Assumptions!$B$8*$A16)/(1-$A16)),0,1,FALSE)-(Assumptions!$B$4*(1-Assumptions!$B$8*$A16)/(1-$A16))*(1-NORMSDIST((Assumptions!$B$4*(1-Assumptions!$B$8*$A16)/(1-$A16))))))+Assumptions!$B$4*(Data!$B4*SQRT(Assumptions!$B$5))*Assumptions!$B$8*$A16*(Data!$D4*(1-Assumptions!$B$7))*E$10+(Data!$B4*SQRT(Assumptions!$B$5))*Assumptions!$B$9*(Data!$D4*Assumptions!$B$7)*((NORMDIST(Assumptions!$B$4,0,1,FALSE)-Assumptions!$B$4*(1-NORMSDIST(Assumptions!$B$4)))-(1-$A16)*(NORMDIST((Assumptions!$B$4*(1-Assumptions!$B$8*$A16)/(1-$A16)),0,1,FALSE)-(Assumptions!$B$4*(1-Assumptions!$B$8*$A16)/(1-$A16))*(1-NORMSDIST((Assumptions!$B$4*(1-Assumptions!$B$8*$A16)/(1-$A16)))))) | F16: =Assumptions!$B$4*(Data!$B2*SQRT(Assumptions!$B$5))*Assumptions!$B$8*$A16*(Data!$D2*(1-Assumptions!$B$7))*F$10+(Data!$B2*SQRT(Assumptions!$B$5))*Assumptions!$B$9*(Data!$D2*Assumptions!$B$7)*((NORMDIST(Assumptions!$B$4,0,1,FALSE)-Assumptions!$B$4*(1-NORMSDIST(Assumptions!$B$4)))-(1-$A16)*(NORMDIST((Assumptions!$B$4*(1-Assumptions!$B$8*$A16)/(1-$A16)),0,1,FALSE)-(Assumptions!$B$4*(1-Assumptions!$B$8*$A16)/(1-$A16))*(1-NORMSDIST((Assumptions!$B$4*(1-Assumptions!$B$8*$A16)/(1-$A16))))))+Assumptions!$B$4*(Data!$B3*SQRT(Assumptions!$B$5))*Assumptions!$B$8*$A16*(Data!$D3*(1-Assumptions!$B$7))*F$10+(Data!$B3*SQRT(Assumptions!$B$5))*Assumptions!$B$9*(Data!$D3*Assumptions!$B$7)*((NORMDIST(Assumptions!$B$4,0,1,FALSE)-Assumptions!$B$4*(1-NORMSDIST(Assumptions!$B$4)))-(1-$A16)*(NORMDIST((Assumptions!$B$4*(1-Assumptions!$B$8*$A16)/(1-$A16)),0,1,FALSE)-(Assumptions!$B$4*(1-Assumptions!$B$8*$A16)/(1-$A16))*(1-NORMSDIST((Assumptions!$B$4*(1-Assumptions!$B$8*$A16)/(1-$A16))))))+Assumptions!$B$4*(Data!$B4*SQRT(Assumptions!$B$5))*Assumptions!$B$8*$A16*(Data!$D4*(1-Assumptions!$B$7))*F$10+(Data!$B4*SQRT(Assumptions!$B$5))*Assumptions!$B$9*(Data!$D4*Assumptions!$B$7)*((NORMDIST(Assumptions!$B$4,0,1,FALSE)-Assumptions!$B$4*(1-NORMSDIST(Assumptions!$B$4)))-(1-$A16)*(NORMDIST((Assumptions!$B$4*(1-Assumptions!$B$8*$A16)/(1-$A16)),0,1,FALSE)-(Assumptions!$B$4*(1-Assumptions!$B$8*$A16)/(1-$A16))*(1-NORMSDIST((Assumptions!$B$4*(1-Assumptions!$B$8*$A16)/(1-$A16)))))) | G16: =Assumptions!$B$4*(Data!$B2*SQRT(Assumptions!$B$5))*Assumptions!$B$8*$A16*(Data!$D2*(1-Assumptions!$B$7))*G$10+(Data!$B2*SQRT(Assumptions!$B$5))*Assumptions!$B$9*(Data!$D2*Assumptions!$B$7)*((NORMDIST(Assumptions!$B$4,0,1,FALSE)-Assumptions!$B$4*(1-NORMSDIST(Assumptions!$B$4)))-(1-$A16)*(NORMDIST((Assumptions!$B$4*(1-Assumptions!$B$8*$A16)/(1-$A16)),0,1,FALSE)-(Assumptions!$B$4*(1-Assumptions!$B$8*$A16)/(1-$A16))*(1-NORMSDIST((Assumptions!$B$4*(1-Assumptions!$B$8*$A16)/(1-$A16))))))+Assumptions!$B$4*(Data!$B3*SQRT(Assumptions!$B$5))*Assumptions!$B$8*$A16*(Data!$D3*(1-Assumptions!$B$7))*G$10+(Data!$B3*SQRT(Assumptions!$B$5))*Assumptions!$B$9*(Data!$D3*Assumptions!$B$7)*((NORMDIST(Assumptions!$B$4,0,1,FALSE)-Assumptions!$B$4*(1-NORMSDIST(Assumptions!$B$4)))-(1-$A16)*(NORMDIST((Assumptions!$B$4*(1-Assumptions!$B$8*$A16)/(1-$A16)),0,1,FALSE)-(Assumptions!$B$4*(1-Assumptions!$B$8*$A16)/(1-$A16))*(1-NORMSDIST((Assumptions!$B$4*(1-Assumptions!$B$8*$A16)/(1-$A16))))))+Assumptions!$B$4*(Data!$B4*SQRT(Assumptions!$B$5))*Assumptions!$B$8*$A16*(Data!$D4*(1-Assumptions!$B$7))*G$10+(Data!$B4*SQRT(Assumptions!$B$5))*Assumptions!$B$9*(Data!$D4*Assumptions!$B$7)*((NORMDIST(Assumptions!$B$4,0,1,FALSE)-Assumptions!$B$4*(1-NORMSDIST(Assumptions!$B$4)))-(1-$A16)*(NORMDIST((Assumptions!$B$4*(1-Assumptions!$B$8*$A16)/(1-$A16)),0,1,FALSE)-(Assumptions!$B$4*(1-Assumptions!$B$8*$A16)/(1-$A16))*(1-NORMSDIST((Assumptions!$B$4*(1-Assumptions!$B$8*$A16)/(1-$A16))))))

Sheet Assumptions
A1: Inventory ROI model - assumptions (yellow cells are inputs)
A3: Service level | B3: 0.95 | C3: Target in-stock probability per replenishment cycle
A4: z (service level) | B4: =NORMSINV(B3) | C4: Derived
A5: Lead time (days) | B5: 7 | C5: Replenishment lead time = review period
A6: Holding cost (% of inventory value / yr) | B6: 0.25 | C6: Capital + storage + shrink
A7: Gross margin on lost sales | B7: 0.3 | C7: Margin lost on each unit short; unit cost = price x (1 - margin)
A8: Share of accuracy gain taken as lower inventory | B8: 0.5 | C8: Remainder is kept as extra service (fewer stockouts)
A9: Replenishment cycles per year | B9: =365/B5 | C9: Derived
A11: Safety stock = z x sum(sigma_i) x sqrt(lead time); sigma_i = std dev of daily forecast error of series i.
A12: Baseline = moving_avg_28; model = lightgbm. Error sigmas come from the 13-fold rolling backtest (src/evaluation/roi.py).
A13: Realisation: share of the backtest accuracy gain assumed to hold in production (Conservative 50% / Expected 75% / Optimistic 100%).
A14: NOTE: dollar values are computed on SYNTHETIC sample data unless the real M5 dataset was loaded.

Sheet Data
A1: Category | B1: Sum of series sigma - baseline | C1: Sum of series sigma - model | D1: Avg selling price ($/unit) | E1: Annual units
A2: FOODS | B2: 643.28631 | C2: 607.82247 | D2: 3.5363736 | E2: 270008.75
A3: HOBBIES | B3: 201.75881 | C3: 196.47945 | D3: 6.2364239 | E3: 63937.415
A4: HOUSEHOLD | B4: 291.33651 | C4: 281.37116 | D4: 8.5106665 | E4: 112429.49

Sheet Scenarios
A1: Scenario | B1: Realisation of backtest gain | C1: Category | D1: Accuracy dividend D | E1: Safety stock before ($) | F1: Safety stock reduction (%) | G1: Safety stock released ($) | H1: Effective z after | I1: Stockout reduction (%) | J1: Holding-cost savings ($/yr) | K1: Stockout margin recovered ($/yr) | L1: Total savings ($/yr) | M1: Shortage cost before ($/yr)
A2: Conservative | B2: 0.5 | C2: =Data!A2 | D2: =B2*(1-Data!C2/Data!B2) | E2: =Assumptions!$B$4*(Data!$B2*SQRT(Assumptions!$B$5))*(Data!$D2*(1-Assumptions!$B$7)) | F2: =Assumptions!$B$8*D2 | G2: =E2*F2 | H2: =Assumptions!$B$4*(1-Assumptions!$B$8*D2)/(1-D2) | I2: =1-((1-D2)*(NORMDIST(H2,0,1,FALSE)-H2*(1-NORMSDIST(H2))))/(NORMDIST(Assumptions!$B$4,0,1,FALSE)-Assumptions!$B$4*(1-NORMSDIST(Assumptions!$B$4))) | J2: =G2*Assumptions!$B$6 | K2: =M2*I2 | L2: =J2+K2 | M2: =(Data!$B2*SQRT(Assumptions!$B$5))*(NORMDIST(Assumptions!$B$4,0,1,FALSE)-Assumptions!$B$4*(1-NORMSDIST(Assumptions!$B$4)))*Assumptions!$B$9*(Data!$D2*Assumptions!$B$7)
A3: Conservative | B3: 0.5 | C3: =Data!A3 | D3: =B3*(1-Data!C3/Data!B3) | E3: =Assumptions!$B$4*(Data!$B3*SQRT(Assumptions!$B$5))*(Data!$D3*(1-Assumptions!$B$7)) | F3: =Assumptions!$B$8*D3 | G3: =E3*F3 | H3: =Assumptions!$B$4*(1-Assumptions!$B$8*D3)/(1-D3) | I3: =1-((1-D3)*(NORMDIST(H3,0,1,FALSE)-H3*(1-NORMSDIST(H3))))/(NORMDIST(Assumptions!$B$4,0,1,FALSE)-Assumptions!$B$4*(1-NORMSDIST(Assumptions!$B$4))) | J3: =G3*Assumptions!$B$6 | K3: =M3*I3 | L3: =J3+K3 | M3: =(Data!$B3*SQRT(Assumptions!$B$5))*(NORMDIST(Assumptions!$B$4,0,1,FALSE)-Assumptions!$B$4*(1-NORMSDIST(Assumptions!$B$4)))*Assumptions!$B$9*(Data!$D3*Assumptions!$B$7)
A4: Conservative | B4: 0.5 | C4: =Data!A4 | D4: =B4*(1-Data!C4/Data!B4) | E4: =Assumptions!$B$4*(Data!$B4*SQRT(Assumptions!$B$5))*(Data!$D4*(1-Assumptions!$B$7)) | F4: =Assumptions!$B$8*D4 | G4: =E4*F4 | H4: =Assumptions!$B$4*(1-Assumptions!$B$8*D4)/(1-D4) | I4: =1-((1-D4)*(NORMDIST(H4,0,1,FALSE)-H4*(1-NORMSDIST(H4))))/(NORMDIST(Assumptions!$B$4,0,1,FALSE)-Assumptions!$B$4*(1-NORMSDIST(Assumptions!$B$4))) | J4: =G4*Assumptions!$B$6 | K4: =M4*I4 | L4: =J4+K4 | M4: =(Data!$B4*SQRT(Assumptions!$B$5))*(NORMDIST(Assumptions!$B$4,0,1,FALSE)-Assumptions!$B$4*(1-NORMSDIST(Assumptions!$B$4)))*Assumptions!$B$9*(Data!$D4*Assumptions!$B$7)
A5: Expected | B5: 0.75 | C5: =Data!A2 | D5: =B5*(1-Data!C2/Data!B2) | E5: =Assumptions!$B$4*(Data!$B2*SQRT(Assumptions!$B$5))*(Data!$D2*(1-Assumptions!$B$7)) | F5: =Assumptions!$B$8*D5 | G5: =E5*F5 | H5: =Assumptions!$B$4*(1-Assumptions!$B$8*D5)/(1-D5) | I5: =1-((1-D5)*(NORMDIST(H5,0,1,FALSE)-H5*(1-NORMSDIST(H5))))/(NORMDIST(Assumptions!$B$4,0,1,FALSE)-Assumptions!$B$4*(1-NORMSDIST(Assumptions!$B$4))) | J5: =G5*Assumptions!$B$6 | K5: =M5*I5 | L5: =J5+K5 | M5: =(Data!$B2*SQRT(Assumptions!$B$5))*(NORMDIST(Assumptions!$B$4,0,1,FALSE)-Assumptions!$B$4*(1-NORMSDIST(Assumptions!$B$4)))*Assumptions!$B$9*(Data!$D2*Assumptions!$B$7)
A6: Expected | B6: 0.75 | C6: =Data!A3 | D6: =B6*(1-Data!C3/Data!B3) | E6: =Assumptions!$B$4*(Data!$B3*SQRT(Assumptions!$B$5))*(Data!$D3*(1-Assumptions!$B$7)) | F6: =Assumptions!$B$8*D6 | G6: =E6*F6 | H6: =Assumptions!$B$4*(1-Assumptions!$B$8*D6)/(1-D6) | I6: =1-((1-D6)*(NORMDIST(H6,0,1,FALSE)-H6*(1-NORMSDIST(H6))))/(NORMDIST(Assumptions!$B$4,0,1,FALSE)-Assumptions!$B$4*(1-NORMSDIST(Assumptions!$B$4))) | J6: =G6*Assumptions!$B$6 | K6: =M6*I6 | L6: =J6+K6 | M6: =(Data!$B3*SQRT(Assumptions!$B$5))*(NORMDIST(Assumptions!$B$4,0,1,FALSE)-Assumptions!$B$4*(1-NORMSDIST(Assumptions!$B$4)))*Assumptions!$B$9*(Data!$D3*Assumptions!$B$7)
A7: Expected | B7: 0.75 | C7: =Data!A4 | D7: =B7*(1-Data!C4/Data!B4) | E7: =Assumptions!$B$4*(Data!$B4*SQRT(Assumptions!$B$5))*(Data!$D4*(1-Assumptions!$B$7)) | F7: =Assumptions!$B$8*D7 | G7: =E7*F7 | H7: =Assumptions!$B$4*(1-Assumptions!$B$8*D7)/(1-D7) | I7: =1-((1-D7)*(NORMDIST(H7,0,1,FALSE)-H7*(1-NORMSDIST(H7))))/(NORMDIST(Assumptions!$B$4,0,1,FALSE)-Assumptions!$B$4*(1-NORMSDIST(Assumptions!$B$4))) | J7: =G7*Assumptions!$B$6 | K7: =M7*I7 | L7: =J7+K7 | M7: =(Data!$B4*SQRT(Assumptions!$B$5))*(NORMDIST(Assumptions!$B$4,0,1,FALSE)-Assumptions!$B$4*(1-NORMSDIST(Assumptions!$B$4)))*Assumptions!$B$9*(Data!$D4*Assumptions!$B$7)
